Workbook

Sheet DPR
A1: DPR - RAPORT MUJOR - QERSHOR 2026
A2: NR | B2: KOMERCIAL | C2: 1 | D2: 2 | E2: 3 | F2: 4 | G2: 5 | H2: 6 | I2: 7 | J2: 8 | K2: 9 | L2: 10 | M2: 11 | N2: 12 | O2: 13 | P2: 14 | Q2: 15 | R2: 16 | S2: 17 | T2: 18 | U2: 19 | V2: 20 | W2: 21 | X2: 22 | Y2: 23 | Z2: 24 | AA2: 25 | AB2: 26 | AC2: 27 | AD2: 28 | AE2: 29 | AF2: 30 | AG2: 31 | AI2: Totali
A3: 1 | B3: Kontrollimi periodik i GM | C3: ='01.07.2026'!C5 -> 0 | D3: ='02.07.2026'!C5 -> 0 | E3: ='03.07.2026'!C5 -> 4 | F3: ='04.07.2026'!C5 -> 0 | H3: ='06.07.2026'!C5 -> 6 | I3: ='07.07.2026'!C5 -> 16 | J3: ='08.07.2026'!C5 -> 13 | K3: ='09.07.2026'!C5 -> 9 | L3: ='10.07.2026'!C5 -> 16 | M3: ='11.07.2026'!C5 -> 0 | O3: ='13.07.2026'!C5 -> 15 | P3: ='14.07.2026'!C5 -> 14 | Q3: ='15.07.2026'!C5 -> 11 | R3: ='16.07.2026'!C5 -> 16 | S3: ='17.07.2026'!C5 -> 11 | T3: ='18.07.2026'!C5 -> 0 | V3: ='20.07.2026'!C5 -> 14 | W3: ='21.07.2026'!C5 -> 11 | X3: ='22.07.2026'!C5 -> 4 | Y3: ='23.07.2026'!C5 -> 13 | Z3: ='24.07.2026'!C5 -> 6 | AA3: ='25.07.2026'!C5 -> 0 | AC3: ='27.07.2026'!C5 -> 13 | AD3: ='28.07.2026'!C5 -> 4 | AE3: ='29.07.2026'!C5 -> 6 | AF3: ='30.07.2026'!C5 -> 4 | AG3: ='31.07.2026'!C5 -> 6 | AI3: =SUM(C3:AF3) -> 206
A4: 2 | B4: Kontrollimi sipas DV i GM | C4: ='01.07.2026'!C6 -> 0 | D4: ='02.07.2026'!C6 -> 0 | E4: ='03.07.2026'!C6 -> 0 | F4: ='04.07.2026'!C6 -> 0 | H4: ='06.07.2026'!C6 -> 0 | I4: ='07.07.2026'!C6 -> 0 | J4: ='08.07.2026'!C6 -> 0 | K4: ='09.07.2026'!C6 -> 0 | L4: ='10.07.2026'!C6 -> 0 | M4: ='11.07.2026'!C6 -> 0 | O4: ='13.07.2026'!C6 -> 0 | P4: ='14.07.2026'!C6 -> 0 | Q4: ='15.07.2026'!C6 -> 0 | R4: ='16.07.2026'!C6 -> 0 | S4: ='17.07.2026'!C6 -> 0 | T4: ='18.07.2026'!C6 -> 0 | V4: ='20.07.2026'!C6 -> 0 | W4: ='21.07.2026'!C6 -> 0 | X4: ='22.07.2026'!C6 -> 0 | Y4: ='23.07.2026'!C6 -> 0 | Z4: ='24.07.2026'!C6 -> 0 | AA4: ='25.07.2026'!C6 -> 0 | AC4: ='27.07.2026'!C6 -> 0 | AD4: ='28.07.2026'!C6 -> 0 | AE4: ='29.07.2026'!C6 -> 0 | AF4: ='30.07.2026'!C6 -> 0 | AG4: ='31.07.2026'!C6 -> 0 | AI4: =SUM(C4:AF4) -> 0
A5: 3 | B5: Ndërrimi i TMRR-ve | C5: ='01.07.2026'!C7 -> 0 | D5: ='02.07.2026'!C7 -> 0 | E5: ='03.07.2026'!C7 -> 0 | F5: ='04.07.2026'!C7 -> 0 | H5: ='06.07.2026'!C7 -> 0 | I5: ='07.07.2026'!C7 -> 0 | J5: ='08.07.2026'!C7 -> 0 | K5: ='09.07.2026'!C7 -> 2 | L5: ='10.07.2026'!C7 -> 0 | M5: ='11.07.2026'!C7 -> 0 | O5: ='13.07.2026'!C7 -> 0 | P5: ='14.07.2026'!C7 -> 0 | Q5: ='15.07.2026'!C7 -> 0 | R5: ='16.07.2026'!C7 -> 0 | S5: ='17.07.2026'!C7 -> 0 | T5: ='18.07.2026'!C7 -> 0 | V5: ='20.07.2026'!C7 -> 0 | W5: ='21.07.2026'!C7 -> 1 | X5: ='22.07.2026'!C7 -> 1 | Y5: ='23.07.2026'!C7 -> 0 | Z5: ='24.07.2026'!C7 -> 0 | AA5: ='25.07.2026'!C7 -> 0 | AC5: ='27.07.2026'!C7 -> 0 | AD5: ='28.07.2026'!C7 -> 0 | AE5: ='29.07.2026'!C7 -> 0 | AF5: ='30.07.2026'!C7 -> 0 | AG5: ='31.07.2026'!C7 -> 0 | AI5: =SUM(C5:AF5) -> 4
A6: 4 | B6: Ndërrimi i njehsorit | C6: ='01.07.2026'!C8 -> 0 | D6: ='02.07.2026'!C8 -> 0 | E6: ='03.07.2026'!C8 -> 0 | F6: ='04.07.2026'!C8 -> 4 | H6: ='06.07.2026'!C8 -> 1 | I6: ='07.07.2026'!C8 -> 1 | J6: ='08.07.2026'!C8 -> 0 | K6: ='09.07.2026'!C8 -> 0 | L6: ='10.07.2026'!C8 -> 0 | M6: ='11.07.2026'!C8 -> 0 | O6: ='13.07.2026'!C8 -> 0 | P6: ='14.07.2026'!C8 -> 0 | Q6: ='15.07.2026'!C8 -> 0 | R6: ='16.07.2026'!C8 -> 0 | S6: ='17.07.2026'!C8 -> 0 | T6: ='18.07.2026'!C8 -> 0 | V6: ='20.07.2026'!C8 -> 0 | W6: ='21.07.2026'!C8 -> 0 | X6: ='22.07.2026'!C8 -> 0 | Y6: ='23.07.2026'!C8 -> 0 | Z6: ='24.07.2026'!C8 -> 0 | AA6: ='25.07.2026'!C8 -> 0 | AC6: ='27.07.2026'!C8 -> 0 | AD6: ='28.07.2026'!C8 -> 0 | AE6: ='29.07.2026'!C8 -> 0 | AF6: ='30.07.2026'!C8 -> 0 | AG6: ='31.07.2026'!C8 -> 0 | AI6: =SUM(C6:AF6) -> 6
A7: 5 | B7: Montimet e GM me PEE | C7: ='01.07.2026'!C9 -> 0 | D7: ='02.07.2026'!C9 -> 1 | E7: ='03.07.2026'!C9 -> 6 | F7: ='04.07.2026'!C9 -> 1 | H7: ='06.07.2026'!C9 -> 0 | I7: ='07.07.2026'!C9 -> 0 | J7: ='08.07.2026'!C9 -> 0 | K7: ='09.07.2026'!C9 -> 0 | L7: ='10.07.2026'!C9 -> 0 | M7: ='11.07.2026'!C9 -> 0 | O7: ='13.07.2026'!C9 -> 0 | P7: ='14.07.2026'!C9 -> 0 | Q7: ='15.07.2026'!C9 -> 1 | R7: ='16.07.2026'!C9 -> 0 | S7: ='17.07.2026'!C9 -> 1 | T7: ='18.07.2026'!C9 -> 0 | V7: ='20.07.2026'!C9 -> 0 | W7: ='21.07.2026'!C9 -> 0 | X7: ='22.07.2026'!C9 -> 1 | Y7: ='23.07.2026'!C9 -> 0 | Z7: ='24.07.2026'!C9 -> 0 | AA7: ='25.07.2026'!C9 -> 0 | AC7: ='27.07.2026'!C9 -> 0 | AD7: ='28.07.2026'!C9 -> 1 | AE7: ='29.07.2026'!C9 -> 0 | AF7: ='30.07.2026'!C9 -> 0 | AG7: ='31.07.2026'!C9 -> 0 | AI7: =SUM(C7:AF7) -> 12
A8: 6 | B8: Kontrollime me kërkesë të konsumatorit | C8: ='01.07.2026'!C10 -> 0 | D8: ='02.07.2026'!C10 -> 0 | E8: ='03.07.2026'!C10 -> 0 | F8: ='04.07.2026'!C10 -> 0 | H8: ='06.07.2026'!C10 -> 0 | I8: ='07.07.2026'!C10 -> 0 | J8: ='08.07.2026'!C10 -> 0 | K8: ='09.07.2026'!C10 -> 0 | L8: ='10.07.2026'!C10 -> 0 | M8: ='11.07.2026'!C10 -> 0 | O8: ='13.07.2026'!C10 -> 0 | P8: ='14.07.2026'!C10 -> 0 | Q8: ='15.07.2026'!C10 -> 0 | R8: ='16.07.2026'!C10 -> 0 | S8: ='17.07.2026'!C10 -> 0 | T8: ='18.07.2026'!C10 -> 0 | V8: ='20.07.2026'!C10 -> 0 | W8: ='21.07.2026'!C10 -> 0 | X8: ='22.07.2026'!C10 -> 0 | Y8: ='23.07.2026'!C10 -> 0 | Z8: ='24.07.2026'!C10 -> 0 | AA8: ='25.07.2026'!C10 -> 0 | AC8: ='27.07.2026'!C10 -> 0 | AD8: ='28.07.2026'!C10 -> 0 | AE8: ='29.07.2026'!C10 -> 0 | AF8: ='30.07.2026'!C10 -> 0 | AG8: ='31.07.2026'!C10 -> 0 | AI8: =SUM(C8:AF8) -> 0
A9: 7 | B9: Rregullimi i lidhjes | C9: ='01.07.2026'!C11 -> 0 | D9: ='02.07.2026'!C11 -> 0 | E9: ='03.07.2026'!C11 -> 0 | F9: ='04.07.2026'!C11 -> 0 | H9: ='06.07.2026'!C11 -> 0 | I9: ='07.07.2026'!C11 -> 0 | J9: ='08.07.2026'!C11 -> 0 | K9: ='09.07.2026'!C11 -> 0 | L9: ='10.07.2026'!C11 -> 0 | M9: ='11.07.2026'!C11 -> 0 | O9: ='13.07.2026'!C11 -> 0 | P9: ='14.07.2026'!C11 -> 0 | Q9: ='15.07.2026'!C11 -> 0 | R9: ='16.07.2026'!C11 -> 2 | S9: ='17.07.2026'!C11 -> 0 | T9: ='18.07.2026'!C11 -> 0 | V9: ='20.07.2026'!C11 -> 0 | W9: ='21.07.2026'!C11 -> 0 | X9: ='22.07.2026'!C11 -> 0 | Y9: ='23.07.2026'!C11 -> 0 | Z9: ='24.07.2026'!C11 -> 0 | AA9: ='25.07.2026'!C11 -> 0 | AC9: ='27.07.2026'!C11 -> 0 | AD9: ='28.07.2026'!C11 -> 0 | AE9: ='29.07.2026'!C11 -> 0 | AF9: ='30.07.2026'!C11 -> 0 | AG9: ='31.07.2026'!C11 -> 0 | AI9: =SUM(C9:AF9) -> 2
A10: 8 | B10: Rregullim i komunikimit | C10: ='01.07.2026'!C12 -> 7 | D10: ='02.07.2026'!C12 -> 3 | E10: ='03.07.2026'!C12 -> 0 | F10: ='04.07.2026'!C12 -> 0 | H10: ='06.07.2026'!C12 -> 0 | I10: ='07.07.2026'!C12 -> 0 | J10: ='08.07.2026'!C12 -> 0 | K10: ='09.07.2026'!C12 -> 0 | L10: ='10.07.2026'!C12 -> 0 | M10: ='11.07.2026'!C12 -> 0 | O10: ='13.07.2026'!C12 -> 0 | P10: ='14.07.2026'!C12 -> 0 | Q10: ='15.07.2026'!C12 -> 0 | R10: ='16.07.2026'!C12 -> 0 | S10: ='17.07.2026'!C12 -> 0 | T10: ='18.07.2026'!C12 -> 0 | V10: ='20.07.2026'!C12 -> 0 | W10: ='21.07.2026'!C12 -> 0 | X10: ='22.07.2026'!C12 -> 0 | Y10: ='23.07.2026'!C12 -> 0 | Z10: ='24.07.2026'!C12 -> 0 | AA10: ='25.07.2026'!C12 -> 0 | AC10: ='27.07.2026'!C12 -> 0 | AD10: ='28.07.2026'!C12 -> 0 | AE10: ='29.07.2026'!C12 -> 0 | AF10: ='30.07.2026'!C12 -> 0 | AG10: ='31.07.2026'!C12 -> 0 | AI10: =SUM(C10:AF10) -> 10
A11: 9 | B11: Lexim | C11: ='01.07.2026'!C13 -> 33 | D11: ='02.07.2026'!C13 -> 3 | E11: ='03.07.2026'!C13 -> 0 | F11: ='04.07.2026'!C13 -> 0 | H11: ='06.07.2026'!C13 -> 1 | I11: ='07.07.2026'!C13 -> 0 | J11: ='08.07.2026'!C13 -> 0 | K11: ='09.07.2026'!C13 -> 0 | L11: ='10.07.2026'!C13 -> 0 | M11: ='11.07.2026'!C13 -> 0 | O11: ='13.07.2026'!C13 -> 0 | P11: ='14.07.2026'!C13 -> 0 | Q11: ='15.07.2026'!C13 -> 0 | R11: ='16.07.2026'!C13 -> 0 | S11: ='17.07.2026'!C13 -> 0 | T11: ='18.07.2026'!C13 -> 0 | V11: ='20.07.2026'!C13 -> 0 | W11: ='21.07.2026'!C13 -> 0 | X11: ='22.07.2026'!C13 -> 0 | Y11: ='23.07.2026'!C13 -> 0 | Z11: ='24.07.2026'!C13 -> 0 | AA11: ='25.07.2026'!C13 -> 0 | AC11: ='27.07.2026'!C13 -> 0 | AD11: ='28.07.2026'!C13 -> 0 | AE11: ='29.07.2026'!C13 -> 0 | AF11: ='30.07.2026'!C13 -> 0 | AG11: ='31.07.2026'!C13 -> 15 | AI11: =SUM(C11:AF11) -> 37
B13: TRAFOREGJIONE
A14: 1 | B14: Kontrollimi i GM | C14: ='01.07.2026'!C16 -> 0 | D14: ='02.07.2026'!C16 -> 0 | E14: ='03.07.2026'!C16 -> 11 | F14: ='04.07.2026'!C16 -> 18 | H14: ='06.07.2026'!C16 -> 16 | I14: ='07.07.2026'!C16 -> 16 | J14: ='08.07.2026'!C16 -> 14 | K14: ='09.07.2026'!C16 -> 16 | L14: ='10.07.2026'!C16 -> 16 | M14: ='11.07.2026'!C16 -> 0 | O14: ='13.07.2026'!C16 -> 12 | P14: ='14.07.2026'!C16 -> 14 | Q14: ='15.07.2026'!C16 -> 0 | R14: ='16.07.2026'!C16 -> 0 | S14: ='17.07.2026'!C16 -> 2 | T14: ='18.07.2026'!C16 -> 0 | V14: ='20.07.2026'!C16 -> 0 | W14: ='21.07.2026'!C16 -> 0 | X14: ='22.07.2026'!C16 -> 0 | Y14: ='23.07.2026'!C16 -> 2 | Z14: ='24.07.2026'!C16 -> 2 | AA14: ='25.07.2026'!C16 -> 0 | AC14: ='27.07.2026'!C16 -> 1 | AD14: ='28.07.2026'!C16 -> 9 | AE14: ='29.07.2026'!C16 -> 13 | AF14: ='30.07.2026'!C16 -> 16 | AG14: ='31.07.2026'!C16 -> 7 | AI14: =SUM(C14:AF14) -> 178
A15: 2 | B15: Nderrimi i TMRR-ve | C15: ='01.07.2026'!C17 -> 0 | D15: ='02.07.2026'!C17 -> 0 | E15: ='03.07.2026'!C17 -> 0 | F15: ='04.07.2026'!C17 -> 0 | H15: ='06.07.2026'!C17 -> 0 | I15: ='07.07.2026'!C17 -> 0 | J15: ='08.07.2026'!C17 -> 1 | K15: ='09.07.2026'!C17 -> 0 | L15: ='10.07.2026'!C17 -> 0 | M15: ='11.07.2026'!C17 -> 0 | O15: ='13.07.2026'!C17 -> 0 | P15: ='14.07.2026'!C17 -> 0 | Q15: ='15.07.2026'!C17 -> 0 | R15: ='16.07.2026'!C17 -> 0 | S15: ='17.07.2026'!C17 -> 0 | T15: ='18.07.2026'!C17 -> 0 | V15: ='20.07.2026'!C17 -> 0 | W15: ='21.07.2026'!C17 -> 0 | X15: ='22.07.2026'!C17 -> 0 | Y15: ='23.07.2026'!C17 -> 0 | Z15: ='24.07.2026'!C17 -> 0 | AA15: ='25.07.2026'!C17 -> 0 | AC15: ='27.07.2026'!C17 -> 0 | AD15: ='28.07.2026'!C17 -> 0 | AE15: ='29.07.2026'!C17 -> 0 | AF15: ='30.07.2026'!C17 -> 0 | AG15: ='31.07.2026'!C17 -> 0 | AI15: =SUM(C15:AF15) -> 1
A16: 3 | B16: Ndrrimet i njehsorit | C16: ='01.07.2026'!C18 -> 0 | D16: ='02.07.2026'!C18 -> 0 | E16: ='03.07.2026'!C18 -> 0 | F16: ='04.07.2026'!C18 -> 0 | H16: ='06.07.2026'!C18 -> 0 | I16: ='07.07.2026'!C18 -> 0 | J16: ='08.07.2026'!C18 -> 0 | K16: ='09.07.2026'!C18 -> 0 | L16: ='10.07.2026'!C18 -> 0 | M16: ='11.07.2026'!C18 -> 0 | O16: ='13.07.2026'!C18 -> 0 | P16: ='14.07.2026'!C18 -> 0 | Q16: ='15.07.2026'!C18 -> 0 | R16: ='16.07.2026'!C18 -> 0 | S16: ='17.07.2026'!C18 -> 1 | T16: ='18.07.2026'!C18 -> 0 | V16: ='20.07.2026'!C18 -> 0 | W16: ='21.07.2026'!C18 -> 0 | X16: ='22.07.2026'!C18 -> 0 | Y16: ='23.07.2026'!C18 -> 0 | Z16: ='24.07.2026'!C18 -> 0 | AA16: ='25.07.2026'!C18 -> 0 | AC16: ='27.07.2026'!C18 -> 1 | AD16: ='28.07.2026'!C18 -> 0 | AE16: ='29.07.2026'!C18 -> 0 | AF16: ='30.07.2026'!C18 -> 0 | AG16: ='31.07.2026'!C18 -> 0 | AI16: =SUM(C16:AF16) -> 2
A17: 4 | B17: Montimet e GM | C17: ='01.07.2026'!C19 -> 0 | D17: ='02.07.2026'!C19 -> 0 | E17: ='03.07.2026'!C19 -> 0 | F17: ='04.07.2026'!C19 -> 1 | H17: ='06.07.2026'!C19 -> 0 | I17: ='07.07.2026'!C19 -> 0 | J17: ='08.07.2026'!C19 -> 1 | K17: ='09.07.2026'!C19 -> 0 | L17: ='10.07.2026'!C19 -> 0 | M17: ='11.07.2026'!C19 -> 0 | O17: ='13.07.2026'!C19 -> 0 | P17: ='14.07.2026'!C19 -> 0 | Q17: ='15.07.2026'!C19 -> 1 | R17: ='16.07.2026'!C19 -> 1 | S17: ='17.07.2026'!C19 -> 1 | T17: ='18.07.2026'!C19 -> 0 | V17: ='20.07.2026'!C19 -> 0 | W17: ='21.07.2026'!C19 -> 0 | X17: ='22.07.2026'!C19 -> 1 | Y17: ='23.07.2026'!C19 -> 0 | Z17: ='24.07.2026'!C19 -> 1 | AA17: ='25.07.2026'!C19 -> 0 | AC17: ='27.07.2026'!C19 -> 0 | AD17: ='28.07.2026'!C19 -> 1 | AE17: ='29.07.2026'!C19 -> 0 | AF17: ='30.07.2026'!C19 -> 1 | AG17: ='31.07.2026'!C19 -> 0 | AI17: =SUM(C17:AF17) -> 9
A18: 5 | B18: Rregullimi i lidhjes | C18: ='01.07.2026'!C20 -> 0 | D18: ='02.07.2026'!C20 -> 0 | E18: ='03.07.2026'!C20 -> 0 | F18: ='04.07.2026'!C20 -> 0 | H18: ='06.07.2026'!C20 -> 0 | I18: ='07.07.2026'!C20 -> 0 | J18: ='08.07.2026'!C20 -> 0 | K18: ='09.07.2026'!C20 -> 0 | L18: ='10.07.2026'!C20 -> 0 | M18: ='11.07.2026'!C20 -> 0 | O18: ='13.07.2026'!C20 -> 0 | P18: ='14.07.2026'!C20 -> 0 | Q18: ='15.07.2026'!C20 -> 0 | R18: ='16.07.2026'!C20 -> 0 | S18: ='17.07.2026'!C20 -> 1 | T18: ='18.07.2026'!C20 -> 0 | V18: ='20.07.2026'!C20 -> 0 | W18: ='21.07.2026'!C20 -> 0 | X18: ='22.07.2026'!C20 -> 0 | Y18: ='23.07.2026'!C20 -> 0 | Z18: ='24.07.2026'!C20 -> 0 | AA18: ='25.07.2026'!C20 -> 0 | AC18: ='27.07.2026'!C20 -> 0 | AD18: ='28.07.2026'!C20 -> 1 | AE18: ='29.07.2026'!C20 -> 0 | AF18: ='30.07.2026'!C20 -> 0 | AG18: ='31.07.2026'!C20 -> 0 | AI18: =SUM(C18:AF18) -> 2
A19: 6 | B19: Rregullim i fazimit, antenës, etj | C19: ='01.07.2026'!C21 -> 0 | D19: ='02.07.2026'!C21 -> 0 | E19: ='03.07.2026'!C21 -> 0 | F19: ='04.07.2026'!C21 -> 0 | H19: ='06.07.2026'!C21 -> 0 | I19: ='07.07.2026'!C21 -> 0 | J19: ='08.07.2026'!C21 -> 0 | K19: ='09.07.2026'!C21 -> 0 | L19: ='10.07.2026'!C21 -> 0 | M19: ='11.07.2026'!C21 -> 0 | O19: ='13.07.2026'!C21 -> 0 | P19: ='14.07.2026'!C21 -> 0 | Q19: ='15.07.2026'!C21 -> 0 | R19: ='16.07.2026'!C21 -> 0 | S19: ='17.07.2026'!C21 -> 0 | T19: ='18.07.2026'!C21 -> 0 | V19: ='20.07.2026'!C21 -> 0 | W19: ='21.07.2026'!C21 -> 0 | X19: ='22.07.2026'!C21 -> 0 | Y19: ='23.07.2026'!C21 -> 0 | Z19: ='24.07.2026'!C21 -> 0 | AA19: ='25.07.2026'!C21 -> 0 | AC19: ='27.07.2026'!C21 -> 0 | AD19: ='28.07.2026'!C21 -> 0 | AE19: ='29.07.2026'!C21 -> 0 | AF19: ='30.07.2026'!C21 -> 0 | AG19: ='31.07.2026'!C21 -> 0 | AI19: =SUM(C19:AF19) -> 0
A20: 7 | B20: Mbesin njehsorë të dëmtuar | C20: ='01.07.2026'!C22 -> 0 | D20: ='02.07.2026'!C22 -> 0 | E20: ='03.07.2026'!C22 -> 0 | F20: ='04.07.2026'!C22 -> 0 | H20: ='06.07.2026'!C22 -> 0 | I20: ='07.07.2026'!C22 -> 0 | J20: ='08.07.2026'!C22 -> 0 | K20: ='09.07.2026'!C22 -> 0 | L20: ='10.07.2026'!C22 -> 0 | M20: ='11.07.2026'!C22 -> 0 | O20: ='13.07.2026'!C22 -> 0 | P20: ='14.07.2026'!C22 -> 0 | Q20: ='15.07.2026'!C22 -> 0 | R20: ='16.07.2026'!C22 -> 0 | S20: ='17.07.2026'!C22 -> 0 | T20: ='18.07.2026'!C22 -> 0 | V20: ='20.07.2026'!C22 -> 0 | W20: ='21.07.2026'!C22 -> 0 | X20: ='22.07.2026'!C22 -> 0 | Y20: ='23.07.2026'!C22 -> 0 | Z20: ='24.07.2026'!C22 -> 0 | AA20: ='25.07.2026'!C22 -> 0 | AC20: ='27.07.2026'!C22 -> 0 | AD20: ='28.07.2026'!C22 -> 0 | AE20: ='29.07.2026'!C22 -> 0 | AF20: ='30.07.2026'!C22 -> 0 | AG20: ='31.07.2026'!C22 -> 0 | AI20: =SUM(C20:AF20) -> 0
A21: 8 | B21: Kontrollim sipas humbjeve | C21: ='01.07.2026'!C23 -> 0 | D21: ='02.07.2026'!C23 -> 0 | E21: ='03.07.2026'!C23 -> 0 | F21: ='04.07.2026'!C23 -> 0 | H21: ='06.07.2026'!C23 -> 0 | I21: ='07.07.2026'!C23 -> 0 | J21: ='08.07.2026'!C23 -> 0 | K21: ='09.07.2026'!C23 -> 0 | L21: ='10.07.2026'!C23 -> 0 | M21: ='11.07.2026'!C23 -> 0 | O21: ='13.07.2026'!C23 -> 0 | P21: ='14.07.2026'!C23 -> 0 | Q21: ='15.07.2026'!C23 -> 0 | R21: ='16.07.2026'!C23 -> 0 | S21: ='17.07.2026'!C23 -> 0 | T21: ='18.07.2026'!C23 -> 0 | V21: ='20.07.2026'!C23 -> 0 | W21: ='21.07.2026'!C23 -> 0 | X21: ='22.07.2026'!C23 -> 0 | Y21: ='23.07.2026'!C23 -> 0 | Z21: ='24.07.2026'!C23 -> 0 | AA21: ='25.07.2026'!C23 -> 0 | AC21: ='27.07.2026'!C23 -> 0 | AD21: ='28.07.2026'!C23 -> 0 | AE21: ='29.07.2026'!C23 -> 0 | AF21: ='30.07.2026'!C23 -> 0 | AG21: ='31.07.2026'!C23 -> 0 | AI21: =SUM(C21:AF21) -> 0
A22: 9 | B22: Rregullim pas vendosjes së ormanit të ri | C22: ='01.07.2026'!C24 -> 0 | D22: ='02.07.2026'!C24 -> 0 | E22: ='03.07.2026'!C24 -> 0 | F22: ='04.07.2026'!C24 -> 0 | H22: ='06.07.2026'!C24 -> 0 | I22: ='07.07.2026'!C24 -> 0 | J22: ='08.07.2026'!C24 -> 0 | K22: ='09.07.2026'!C24 -> 0 | L22: ='10.07.2026'!C24 -> 0 | M22: ='11.07.2026'!C24 -> 0 | O22: ='13.07.2026'!C24 -> 0 | P22: ='14.07.2026'!C24 -> 0 | Q22: ='15.07.2026'!C24 -> 0 | R22: ='16.07.2026'!C24 -> 0 | S22: ='17.07.2026'!C24 -> 0 | T22: ='18.07.2026'!C24 -> 0 | V22: ='20.07.2026'!C24 -> 0 | W22: ='21.07.2026'!C24 -> 0 | X22: ='22.07.2026'!C24 -> 0 | Y22: ='23.07.2026'!C24 -> 0 | Z22: ='24.07.2026'!C24 -> 0 | AA22: ='25.07.2026'!C24 -> 0 | AC22: ='27.07.2026'!C24 -> 0 | AD22: ='28.07.2026'!C24 -> 0 | AE22: ='29.07.2026'!C24 -> 0 | AF22: ='30.07.2026'!C24 -> 0 | AG22: ='31.07.2026'!C24 -> 0 | AI22: =SUM(C22:AF22) -> 0
A23: 10 | B23: Ndërrimet e TMRR pas ndërrimit të TR | C23: ='01.07.2026'!C25 -> 0 | D23: ='02.07.2026'!C25 -> 0 | E23: ='03.07.2026'!C25 -> 0 | F23: ='04.07.2026'!C25 -> 0 | H23: ='06.07.2026'!C25 -> 0 | I23: ='07.07.2026'!C25 -> 0 | J23: ='08.07.2026'!C25 -> 0 | K23: ='09.07.2026'!C25 -> 0 | L23: ='10.07.2026'!C25 -> 0 | M23: ='11.07.2026'!C25 -> 0 | O23: ='13.07.2026'!C25 -> 0 | P23: ='14.07.2026'!C25 -> 0 | Q23: ='15.07.2026'!C25 -> 0 | R23: ='16.07.2026'!C25 -> 0 | S23: ='17.07.2026'!C25 -> 0 | T23: ='18.07.2026'!C25 -> 0 | V23: ='20.07.2026'!C25 -> 0 | W23: ='21.07.2026'!C25 -> 0 | X23: ='22.07.2026'!C25 -> 0 | Y23: ='23.07.2026'!C25 -> 0 | Z23: ='24.07.2026'!C25 -> 0 | AA23: ='25.07.2026'!C25 -> 0 | AC23: ='27.07.2026'!C25 -> 0 | AD23: ='28.07.2026'!C25 -> 0 | AE23: ='29.07.2026'!C25 -> 0 | AF23: ='30.07.2026'!C25 -> 0 | AG23: ='31.07.2026'!C25 -> 0 | AI23: =SUM(C23:AF23) -> 0
A24: 11 | B24: Koncentrator | C24: ='01.07.2026'!C26 -> 0 | D24: ='02.07.2026'!C26 -> 1 | E24: ='03.07.2026'!C26 -> 0 | F24: ='04.07.2026'!C26 -> 1 | H24: ='06.07.2026'!C26 -> 0 | I24: ='07.07.2026'!C26 -> 0 | J24: ='08.07.2026'!C26 -> 2 | K24: ='09.07.2026'!C26 -> 0 | L24: ='10.07.2026'!C26 -> 0 | M24: ='11.07.2026'!C26 -> 0 | O24: ='13.07.2026'!C26 -> 0 | P24: ='14.07.2026'!C26 -> 0 | Q24: ='15.07.2026'!C26 -> 0 | R24: ='16.07.2026'!C26 -> 0 | S24: ='17.07.2026'!C26 -> 0 | T24: ='18.07.2026'!C26 -> 0 | V24: ='20.07.2026'!C26 -> 4 | W24: ='21.07.2026'!C26 -> 4 | X24: ='22.07.2026'!C26 -> 0 | Y24: ='23.07.2026'!C26 -> 2 | Z24: ='24.07.2026'!C26 -> 3 | AA24: ='25.07.2026'!C26 -> 0 | AC24: ='27.07.2026'!C26 -> 8 | AD24: ='28.07.2026'!C26 -> 2 | AE24: ='29.07.2026'!C26 -> 1 | AF24: ='30.07.2026'!C26 -> 0 | AG24: ='31.07.2026'!C26 -> 1 | AI24: =SUM(C24:AF24) -> 28
B26: DIREKT
A27: 1 | B27: Lidhje të reja | C27: ='01.07.2026'!C29 -> 0 | D27: ='02.07.2026'!C29 -> 0 | E27: ='03.07.2026'!C29 -> 0 | F27: ='04.07.2026'!C29 -> 0 | H27: ='06.07.2026'!C29 -> 0 | I27: ='07.07.2026'!C29 -> 0 | J27: ='08.07.2026'!C29 -> 0 | K27: ='09.07.2026'!C29 -> 0 | L27: ='10.07.2026'!C29 -> 0 | M27: ='11.07.2026'!C29 -> 0 | O27: ='13.07.2026'!C29 -> 0 | P27: ='14.07.2026'!C29 -> 1 | Q27: ='15.07.2026'!C29 -> 0 | R27: ='16.07.2026'!C29 -> 0 | S27: ='17.07.2026'!C29 -> 0 | T27: ='18.07.2026'!C29 -> 0 | V27: ='20.07.2026'!C29 -> 0 | W27: ='21.07.2026'!C29 -> 0 | X27: ='22.07.2026'!C29 -> 0 | Y27: ='23.07.2026'!C29 -> 0 | Z27: ='24.07.2026'!C29 -> 0 | AA27: ='25.07.2026'!C29 -> 0 | AC27: ='27.07.2026'!C29 -> 0 | AD27: ='28.07.2026'!C29 -> 0 | AE27: ='29.07.2026'!C29 -> 0 | AF27: ='30.07.2026'!C29 -> 0 | AG27: ='31.07.2026'!C29 -> 0 | AI27: =SUM(C27:AF27) -> 1
A28: 2 | B28: Ndërrime | C28: ='01.07.2026'!C30 -> 0 | D28: ='02.07.2026'!C30 -> 1 | E28: ='03.07.2026'!C30 -> 0 | F28: ='04.07.2026'!C30 -> 2 | H28: ='06.07.2026'!C30 -> 0 | I28: ='07.07.2026'!C30 -> 0 | J28: ='08.07.2026'!C30 -> 0 | K28: ='09.07.2026'!C30 -> 0 | L28: ='10.07.2026'!C30 -> 0 | M28: ='11.07.2026'!C30 -> 0 | O28: ='13.07.2026'!C30 -> 0 | P28: ='14.07.2026'!C30 -> 1 | Q28: ='15.07.2026'!C30 -> 4 | R28: ='16.07.2026'!C30 -> 0 | S28: ='17.07.2026'!C30 -> 0 | T28: ='18.07.2026'!C30 -> 0 | V28: ='20.07.2026'!C30 -> 0 | W28: ='21.07.2026'!C30 -> 2 | X28: ='22.07.2026'!C30 -> 4 | Y28: ='23.07.2026'!C30 -> 1 | Z28: ='24.07.2026'!C30 -> 0 | AA28: ='25.07.2026'!C30 -> 0 | AC28: ='27.07.2026'!C30 -> 0 | AD28: ='28.07.2026'!C30 -> 0 | AE28: ='29.07.2026'!C30 -> 0 | AF28: ='30.07.2026'!C30 -> 1 | AG28: ='31.07.2026'!C30 -> 0 | AI28: =SUM(C28:AF28) -> 16
A29: 3 | B29: PLC | C29: ='01.07.2026'!C31 -> 0 | D29: ='02.07.2026'!C31 -> 0 | E29: ='03.07.2026'!C31 -> 0 | F29: ='04.07.2026'!C31 -> 0 | H29: ='06.07.2026'!C31 -> 1 | I29: ='07.07.2026'!C31 -> 0 | J29: ='08.07.2026'!C31 -> 0 | K29: ='09.07.2026'!C31 -> 0 | L29: ='10.07.2026'!C31 -> 0 | M29: ='11.07.2026'!C31 -> 0 | O29: ='13.07.2026'!C31 -> 4 | P29: ='14.07.2026'!C31 -> 0 | Q29: ='15.07.2026'!C31 -> 0 | R29: ='16.07.2026'!C31 -> 3 | S29: ='17.07.2026'!C31 -> 4 | T29: ='18.07.2026'!C31 -> 0 | V29: ='20.07.2026'!C31 -> 0 | W29: ='21.07.2026'!C31 -> 0 | X29: ='22.07.2026'!C31 -> 0 | Y29: ='23.07.2026'!C31 -> 0 | Z29: ='24.07.2026'!C31 -> 0 | AA29: ='25.07.2026'!C31 -> 0 | AC29: ='27.07.2026'!C31 -> 0 | AD29: ='28.07.2026'!C31 -> 0 | AE29: ='29.07.2026'!C31 -> 2 | AF29: ='30.07.2026'!C31 -> 0 | AG29: ='31.07.2026'!C31 -> 0 | AI29: =SUM(C29:AF29) -> 14
A30: 4 | B30: Kontrollim me ZERA | C30: ='01.07.2026'!C32 -> 0 | D30: ='02.07.2026'!C32 -> 0 | E30: ='03.07.2026'!C32 -> 0 | F30: ='04.07.2026'!C32 -> 0 | H30: ='06.07.2026'!C32 -> 0 | I30: ='07.07.2026'!C32 -> 0 | J30: ='08.07.2026'!C32 -> 0 | K30: ='09.07.2026'!C32 -> 0 | L30: ='10.07.2026'!C32 -> 0 | M30: ='11.07.2026'!C32 -> 0 | O30: ='13.07.2026'!C32 -> 0 | P30: ='14.07.2026'!C32 -> 0 | Q30: ='15.07.2026'!C32 -> 0 | R30: ='16.07.2026'!C32 -> 0 | S30: ='17.07.2026'!C32 -> 0 | T30: ='18.07.2026'!C32 -> 0 | V30: ='20.07.2026'!C32 -> 0 | W30: ='21.07.2026'!C32 -> 0 | X30: ='22.07.2026'!C32 -> 0 | Y30: ='23.07.2026'!C32 -> 0 | Z30: ='24.07.2026'!C32 -> 0 | AA30: ='25.07.2026'!C32 -> 0 | AC30: ='27.07.2026'!C32 -> 0 | AD30: ='28.07.2026'!C32 -> 0 | AE30: ='29.07.2026'!C32 -> 0 | AF30: ='30.07.2026'!C32 -> 0 | AG30: ='31.07.2026'!C32 -> 0 | AI30: =SUM(C30:AF30) -> 0
A31: 5 | B31: Rregullim komunikimit dhe tjera | C31: ='01.07.2026'!C33 -> 12 | D31: ='02.07.2026'!C33 -> 15 | E31: ='03.07.2026'!C33 -> 0 | F31: ='04.07.2026'!C33 -> 0 | H31: ='06.07.2026'!C33 -> 0 | I31: ='07.07.2026'!C33 -> 0 | J31: ='08.07.2026'!C33 -> 1 | K31: ='09.07.2026'!C33 -> 0 | L31: ='10.07.2026'!C33 -> 0 | M31: ='11.07.2026'!C33 -> 0 | O31: ='13.07.2026'!C33 -> 0 | P31: ='14.07.2026'!C33 -> 0 | Q31: ='15.07.2026'!C33 -> 0 | R31: ='16.07.2026'!C33 -> 0 | S31: ='17.07.2026'!C33 -> 0 | T31: ='18.07.2026'!C33 -> 0 | V31: ='20.07.2026'!C33 -> 0 | W31: ='21.07.2026'!C33 -> 0 | X31: ='22.07.2026'!C33 -> 0 | Y31: ='23.07.2026'!C33 -> 9 | Z31: ='24.07.2026'!C33 -> 15 | AA31: ='25.07.2026'!C33 -> 0 | AC31: ='27.07.2026'!C33 -> 0 | AD31: ='28.07.2026'!C33 -> 4 | AE31: ='29.07.2026'!C33 -> 0 | AF31: ='30.07.2026'!C33 -> 3 | AG31: ='31.07.2026'!C33 -> 0 | AI31: =SUM(C31:AF31) -> 59

Sheet DMI
A1: DMI - RAPORT MUJOR - QERSHOR 2026
A2: NR | B2: KOMERCIAL | C2: 1 | D2: 2 | E2: 3 | F2: 4 | G2: 5 | H2: 6 | I2: 7 | J2: 8 | K2: 9 | L2: 10 | M2: 11 | N2: 12 | O2: 13 | P2: 14 | Q2: 15 | R2: 16 | S2: 17 | T2: 18 | U2: 19 | V2: 20 | W2: 21 | X2: 22 | Y2: 23 | Z2: 24 | AA2: 25 | AB2: 26 | AC2: 27 | AD2: 28 | AE2: 29 | AF2: 30 | AG2: 31 | AI2: Totali
A3: 1 | B3: Kontrollimi periodik i GM | C3: ='01.07.2026'!D5 -> 0 | D3: ='02.07.2026'!D5 -> 5 | E3: ='03.07.2026'!D5 -> 3 | F3: ='04.07.2026'!D5 -> 4 | H3: ='06.07.2026'!D5 -> 6 | I3: ='07.07.2026'!D5 -> 4 | J3: ='08.07.2026'!D5 -> 6 | K3: ='09.07.2026'!D5 -> 0 | L3: ='10.07.2026'!D5 -> 0 | M3: ='11.07.2026'!D5 -> 0 | O3: ='13.07.2026'!D5 -> 2 | P3: ='14.07.2026'!D5 -> 0 | Q3: ='15.07.2026'!D5 -> 2 | R3: ='16.07.2026'!D5 -> 4 | S3: ='17.07.2026'!D5 -> 2 | T3: ='18.07.2026'!D5 -> 0 | V3: ='20.07.2026'!D5 -> 6 | W3: ='21.07.2026'!D5 -> 1 | X3: ='22.07.2026'!D5 -> 4 | Y3: ='23.07.2026'!D5 -> 3 | Z3: ='24.07.2026'!D5 -> 5 | AA3: ='25.07.2026'!D5 -> 0 | AC3: ='27.07.2026'!D5 -> 0 | AD3: ='28.07.2026'!D5 -> 2 | AE3: ='29.07.2026'!D5 -> 0 | AF3: ='30.07.2026'!D5 -> 0 | AG3: ='31.07.2026'!D5 -> 6 | AI3: =SUM(C3:AF3) -> 59
A4: 2 | B4: Kontrollimi sipas DV i GM | C4: ='01.07.2026'!D6 -> 0 | D4: ='02.07.2026'!D6 -> 0 | E4: ='03.07.2026'!D6 -> 0 | F4: ='04.07.2026'!D6 -> 0 | H4: ='06.07.2026'!D6 -> 0 | I4: ='07.07.2026'!D6 -> 0 | J4: ='08.07.2026'!D6 -> 0 | K4: ='09.07.2026'!D6 -> 0 | L4: ='10.07.2026'!D6 -> 0 | M4: ='11.07.2026'!D6 -> 0 | O4: ='13.07.2026'!D6 -> 0 | P4: ='14.07.2026'!D6 -> 0 | Q4: ='15.07.2026'!D6 -> 0 | R4: ='16.07.2026'!D6 -> 0 | S4: ='17.07.2026'!D6 -> 0 | T4: ='18.07.2026'!D6 -> 0 | V4: ='20.07.2026'!D6 -> 0 | W4: ='21.07.2026'!D6 -> 0 | X4: ='22.07.2026'!D6 -> 0 | Y4: ='23.07.2026'!D6 -> 0 | Z4: ='24.07.2026'!D6 -> 0 | AA4: ='25.07.2026'!D6 -> 0 | AC4: ='27.07.2026'!D6 -> 0 | AD4: ='28.07.2026'!D6 -> 0 | AE4: ='29.07.2026'!D6 -> 0 | AF4: ='30.07.2026'!D6 -> 0 | AG4: ='31.07.2026'!D6 -> 0 | AI4: =SUM(C4:AF4) -> 0
A5: 3 | B5: Ndërrimi i TMRR-ve | C5: ='01.07.2026'!D7 -> 0 | D5: ='02.07.2026'!D7 -> 0 | E5: ='03.07.2026'!D7 -> 0 | F5: ='04.07.2026'!D7 -> 0 | H5: ='06.07.2026'!D7 -> 0 | I5: ='07.07.2026'!D7 -> 0 | J5: ='08.07.2026'!D7 -> 0 | K5: ='09.07.2026'!D7 -> 0 | L5: ='10.07.2026'!D7 -> 0 | M5: ='11.07.2026'!D7 -> 0 | O5: ='13.07.2026'!D7 -> 0 | P5: ='14.07.2026'!D7 -> 0 | Q5: ='15.07.2026'!D7 -> 0 | R5: ='16.07.2026'!D7 -> 0 | S5: ='17.07.2026'!D7 -> 0 | T5: ='18.07.2026'!D7 -> 0 | V5: ='20.07.2026'!D7 -> 0 | W5: ='21.07.2026'!D7 -> 0 | X5: ='22.07.2026'!D7 -> 0 | Y5: ='23.07.2026'!D7 -> 0 | Z5: ='24.07.2026'!D7 -> 0 | AA5: ='25.07.2026'!D7 -> 0 | AC5: ='27.07.2026'!D7 -> 0 | AD5: ='28.07.2026'!D7 -> 0 | AE5: ='29.07.2026'!D7 -> 0 | AF5: ='30.07.2026'!D7 -> 0 | AG5: ='31.07.2026'!D7 -> 0 | AI5: =SUM(C5:AF5) -> 0
A6: 4 | B6: Ndërrimi i njehsorit | C6: ='01.07.2026'!D8 -> 0 | D6: ='02.07.2026'!D8 -> 0 | E6: ='03.07.2026'!D8 -> 0 | F6: ='04.07.2026'!D8 -> 0 | H6: ='06.07.2026'!D8 -> 0 | I6: ='07.07.2026'!D8 -> 0 | J6: ='08.07.2026'!D8 -> 0 | K6: ='09.07.2026'!D8 -> 0 | L6: ='10.07.2026'!D8 -> 0 | M6: ='11.07.2026'!D8 -> 0 | O6: ='13.07.2026'!D8 -> 0 | P6: ='14.07.2026'!D8 -> 0 | Q6: ='15.07.2026'!D8 -> 0 | R6: ='16.07.2026'!D8 -> 0 | S6: ='17.07.2026'!D8 -> 0 | T6: ='18.07.2026'!D8 -> 0 | V6: ='20.07.2026'!D8 -> 0 | W6: ='21.07.2026'!D8 -> 0 | X6: ='22.07.2026'!D8 -> 0 | Y6: ='23.07.2026'!D8 -> 0 | Z6: ='24.07.2026'!D8 -> 0 | AA6: ='25.07.2026'!D8 -> 0 | AC6: ='27.07.2026'!D8 -> 0 | AD6: ='28.07.2026'!D8 -> 0 | AE6: ='29.07.2026'!D8 -> 0 | AF6: ='30.07.2026'!D8 -> 0 | AG6: ='31.07.2026'!D8 -> 0 | AI6: =SUM(C6:AF6) -> 0
A7: 5 | B7: Montimet e GM me PEE | C7: ='01.07.2026'!D9 -> 0 | D7: ='02.07.2026'!D9 -> 0 | E7: ='03.07.2026'!D9 -> 0 | F7: ='04.07.2026'!D9 -> 0 | H7: ='06.07.2026'!D9 -> 0 | I7: ='07.07.2026'!D9 -> 0 | J7: ='08.07.2026'!D9 -> 0 | K7: ='09.07.2026'!D9 -> 0 | L7: ='10.07.2026'!D9 -> 0 | M7: ='11.07.2026'!D9 -> 0 | O7: ='13.07.2026'!D9 -> 1 | P7: ='14.07.2026'!D9 -> 0 | Q7: ='15.07.2026'!D9 -> 0 | R7: ='16.07.2026'!D9 -> 0 | S7: ='17.07.2026'!D9 -> 4 | T7: ='18.07.2026'!D9 -> 0 | V7: ='20.07.2026'!D9 -> 0 | W7: ='21.07.2026'!D9 -> 3 | X7: ='22.07.2026'!D9 -> 0 | Y7: ='23.07.2026'!D9 -> 0 | Z7: ='24.07.2026'!D9 -> 0 | AA7: ='25.07.2026'!D9 -> 0 | AC7: ='27.07.2026'!D9 -> 0 | AD7: ='28.07.2026'!D9 -> 0 | AE7: ='29.07.2026'!D9 -> 0 | AF7: ='30.07.2026'!D9 -> 0 | AG7: ='31.07.2026'!D9 -> 0 | AI7: =SUM(C7:AF7) -> 8
A8: 6 | B8: Kontrollime me kërkesë të konsumatorit | C8: ='01.07.2026'!D10 -> 0 | D8: ='02.07.2026'!D10 -> 0 | E8: ='03.07.2026'!D10 -> 0 | F8: ='04.07.2026'!D10 -> 0 | H8: ='06.07.2026'!D10 -> 0 | I8: ='07.07.2026'!D10 -> 0 | J8: ='08.07.2026'!D10 -> 0 | K8: ='09.07.2026'!D10 -> 0 | L8: ='10.07.2026'!D10 -> 0 | M8: ='11.07.2026'!D10 -> 0 | O8: ='13.07.2026'!D10 -> 0 | P8: ='14.07.2026'!D10 -> 0 | Q8: ='15.07.2026'!D10 -> 0 | R8: ='16.07.2026'!D10 -> 0 | S8: ='17.07.2026'!D10 -> 0 | T8: ='18.07.2026'!D10 -> 0 | V8: ='20.07.2026'!D10 -> 0 | W8: ='21.07.2026'!D10 -> 0 | X8: ='22.07.2026'!D10 -> 0 | Y8: ='23.07.2026'!D10 -> 0 | Z8: ='24.07.2026'!D10 -> 0 | AA8: ='25.07.2026'!D10 -> 0 | AC8: ='27.07.2026'!D10 -> 0 | AD8: ='28.07.2026'!D10 -> 0 | AE8: ='29.07.2026'!D10 -> 0 | AF8: ='30.07.2026'!D10 -> 0 | AG8: ='31.07.2026'!D10 -> 0 | AI8: =SUM(C8:AF8) -> 0
A9: 7 | B9: Rregullimi i lidhjes | C9: ='01.07.2026'!D11 -> 0 | D9: ='02.07.2026'!D11 -> 0 | E9: ='03.07.2026'!D11 -> 0 | F9: ='04.07.2026'!D11 -> 0 | H9: ='06.07.2026'!D11 -> 0 | I9: ='07.07.2026'!D11 -> 0 | J9: ='08.07.2026'!D11 -> 0 | K9: ='09.07.2026'!D11 -> 0 | L9: ='10.07.2026'!D11 -> 0 | M9: ='11.07.2026'!D11 -> 0 | O9: ='13.07.2026'!D11 -> 0 | P9: ='14.07.2026'!D11 -> 0 | Q9: ='15.07.2026'!D11 -> 0 | R9: ='16.07.2026'!D11 -> 0 | S9: ='17.07.2026'!D11 -> 0 | T9: ='18.07.2026'!D11 -> 0 | V9: ='20.07.2026'!D11 -> 0 | W9: ='21.07.2026'!D11 -> 0 | X9: ='22.07.2026'!D11 -> 0 | Y9: ='23.07.2026'!D11 -> 0 | Z9: ='24.07.2026'!D11 -> 0 | AA9: ='25.07.2026'!D11 -> 0 | AC9: ='27.07.2026'!D11 -> 0 | AD9: ='28.07.2026'!D11 -> 0 | AE9: ='29.07.2026'!D11 -> 0 | AF9: ='30.07.2026'!D11 -> 0 | AG9: ='31.07.2026'!D11 -> 0 | AI9: =SUM(C9:AF9) -> 0
A10: 8 | B10: Rregullim i komunikimit | C10: ='01.07.2026'!D12 -> 2 | D10: ='02.07.2026'!D12 -> 0 | E10: ='03.07.2026'!D12 -> 0 | F10: ='04.07.2026'!D12 -> 0 | H10: ='06.07.2026'!D12 -> 0 | I10: ='07.07.2026'!D12 -> 0 | J10: ='08.07.2026'!D12 -> 0 | K10: ='09.07.2026'!D12 -> 0 | L10: ='10.07.2026'!D12 -> 0 | M10: ='11.07.2026'!D12 -> 0 | O10: ='13.07.2026'!D12 -> 0 | P10: ='14.07.2026'!D12 -> 0 | Q10: ='15.07.2026'!D12 -> 0 | R10: ='16.07.2026'!D12 -> 0 | S10: ='17.07.2026'!D12 -> 0 | T10: ='18.07.2026'!D12 -> 0 | V10: ='20.07.2026'!D12 -> 0 | W10: ='21.07.2026'!D12 -> 0 | X10: ='22.07.2026'!D12 -> 2 | Y10: ='23.07.2026'!D12 -> 1 | Z10: ='24.07.2026'!D12 -> 0 | AA10: ='25.07.2026'!D12 -> 0 | AC10: ='27.07.2026'!D12 -> 0 | AD10: ='28.07.2026'!D12 -> 0 | AE10: ='29.07.2026'!D12 -> 0 | AF10: ='30.07.2026'!D12 -> 0 | AG10: ='31.07.2026'!D12 -> 0 | AI10: =SUM(C10:AF10) -> 5
A11: 9 | B11: Lexim | C11: ='01.07.2026'!D13 -> 0 | D11: ='02.07.2026'!D13 -> 0 | E11: ='03.07.2026'!D13 -> 0 | F11: ='04.07.2026'!D13 -> 0 | H11: ='06.07.2026'!D13 -> 0 | I11: ='07.07.2026'!D13 -> 0 | J11: ='08.07.2026'!D13 -> 0 | K11: ='09.07.2026'!D13 -> 0 | L11: ='10.07.2026'!D13 -> 0 | M11: ='11.07.2026'!D13 -> 0 | O11: ='13.07.2026'!D13 -> 0 | P11: ='14.07.2026'!D13 -> 0 | Q11: ='15.07.2026'!D13 -> 0 | R11: ='16.07.2026'!D13 -> 0 | S11: ='17.07.2026'!D13 -> 0 | T11: ='18.07.2026'!D13 -> 0 | V11: ='20.07.2026'!D13 -> 0 | W11: ='21.07.2026'!D13 -> 0 | X11: ='22.07.2026'!D13 -> 0 | Y11: ='23.07.2026'!D13 -> 0 | Z11: ='24.07.2026'!D13 -> 0 | AA11: ='25.07.2026'!D13 -> 0 | AC11: ='27.07.2026'!D13 -> 0 | AD11: ='28.07.2026'!D13 -> 0 | AE11: ='29.07.2026'!D13 -> 0 | AF11: ='30.07.2026'!D13 -> 0 | AG11: ='31.07.2026'!D13 -> 0 | AI11: =SUM(C11:AF11) -> 0
B13: TRAFOREGJIONE
A14: 1 | B14: Kontrollimi i GM | C14: ='01.07.2026'!D16 -> 1 | D14: ='02.07.2026'!D16 -> 6 | E14: ='03.07.2026'!D16 -> 8 | F14: ='04.07.2026'!D16 -> 6 | H14: ='06.07.2026'!D16 -> 6 | I14: ='07.07.2026'!D16 -> 11 | J14: ='08.07.2026'!D16 -> 10 | K14: ='09.07.2026'!D16 -> 15 | L14: ='10.07.2026'!D16 -> 15 | M14: ='11.07.2026'!D16 -> 0 | O14: ='13.07.2026'!D16 -> 9 | P14: ='14.07.2026'!D16 -> 16 | Q14: ='15.07.2026'!D16 -> 14 | R14: ='16.07.2026'!D16 -> 11 | S14: ='17.07.2026'!D16 -> 1 | T14: ='18.07.2026'!D16 -> 0 | V14: ='20.07.2026'!D16 -> 8 | W14: ='21.07.2026'!D16 -> 7 | X14: ='22.07.2026'!D16 -> 4 | Y14: ='23.07.2026'!D16 -> 9 | Z14: ='24.07.2026'!D16 -> 2 | AA14: ='25.07.2026'!D16 -> 0 | AC14: ='27.07.2026'!D16 -> 7 | AD14: ='28.07.2026'!D16 -> 8 | AE14: ='29.07.2026'!D16 -> 0 | AF14: ='30.07.2026'!D16 -> 5 | AG14: ='31.07.2026'!D16 -> 7 | AI14: =SUM(C14:AF14) -> 179
A15: 2 | B15: Nderrimi i TMRR-ve | C15: ='01.07.2026'!D17 -> 0 | D15: ='02.07.2026'!D17 -> 0 | E15: ='03.07.2026'!D17 -> 0 | F15: ='04.07.2026'!D17 -> 0 | H15: ='06.07.2026'!D17 -> 0 | I15: ='07.07.2026'!D17 -> 0 | J15: ='08.07.2026'!D17 -> 0 | K15: ='09.07.2026'!D17 -> 0 | L15: ='10.07.2026'!D17 -> 0 | M15: ='11.07.2026'!D17 -> 0 | O15: ='13.07.2026'!D17 -> 0 | P15: ='14.07.2026'!D17 -> 0 | Q15: ='15.07.2026'!D17 -> 0 | R15: ='16.07.2026'!D17 -> 0 | S15: ='17.07.2026'!D17 -> 0 | T15: ='18.07.2026'!D17 -> 0 | V15: ='20.07.2026'!D17 -> 0 | W15: ='21.07.2026'!D17 -> 0 | X15: ='22.07.2026'!D17 -> 0 | Y15: ='23.07.2026'!D17 -> 0 | Z15: ='24.07.2026'!D17 -> 0 | AA15: ='25.07.2026'!D17 -> 0 | AC15: ='27.07.2026'!D17 -> 0 | AD15: ='28.07.2026'!D17 -> 0 | AE15: ='29.07.2026'!D17 -> 0 | AF15: ='30.07.2026'!D17 -> 0 | AG15: ='31.07.2026'!D17 -> 0 | AI15: =SUM(C15:AF15) -> 0
A16: 3 | B16: Ndrrimet i njehsorit | C16: ='01.07.2026'!D18 -> 0 | D16: ='02.07.2026'!D18 -> 0 | E16: ='03.07.2026'!D18 -> 0 | F16: ='04.07.2026'!D18 -> 0 | H16: ='06.07.2026'!D18 -> 0 | I16: ='07.07.2026'!D18 -> 0 | J16: ='08.07.2026'!D18 -> 0 | K16: ='09.07.2026'!D18 -> 0 | L16: ='10.07.2026'!D18 -> 0 | M16: ='11.07.2026'!D18 -> 0 | O16: ='13.07.2026'!D18 -> 0 | P16: ='14.07.2026'!D18 -> 0 | Q16: ='15.07.2026'!D18 -> 0 | R16: ='16.07.2026'!D18 -> 0 | S16: ='17.07.2026'!D18 -> 0 | T16: ='18.07.2026'!D18 -> 0 | V16: ='20.07.2026'!D18 -> 0 | W16: ='21.07.2026'!D18 -> 0 | X16: ='22.07.2026'!D18 -> 0 | Y16: ='23.07.2026'!D18 -> 0 | Z16: ='24.07.2026'!D18 -> 1 | AA16: ='25.07.2026'!D18 -> 0 | AC16: ='27.07.2026'!D18 -> 0 | AD16: ='28.07.2026'!D18 -> 0 | AE16: ='29.07.2026'!D18 -> 1 | AF16: ='30.07.2026'!D18 -> 2 | AG16: ='31.07.2026'!D18 -> 0 | AI16: =SUM(C16:AF16) -> 4
A17: 4 | B17: Montimet e GM | C17: ='01.07.2026'!D19 -> 1 | D17: ='02.07.2026'!D19 -> 1 | E17: ='03.07.2026'!D19 -> 0 | F17: ='04.07.2026'!D19 -> 0 | H17: ='06.07.2026'!D19 -> 0 | I17: ='07.07.2026'!D19 -> 0 | J17: ='08.07.2026'!D19 -> 0 | K17: ='09.07.2026'!D19 -> 1 | L17: ='10.07.2026'!D19 -> 1 | M17: ='11.07.2026'!D19 -> 0 | O17: ='13.07.2026'!D19 -> 1 | P17: ='14.07.2026'!D19 -> 0 | Q17: ='15.07.2026'!D19 -> 0 | R17: ='16.07.2026'!D19 -> 0 | S17: ='17.07.2026'!D19 -> 1 | T17: ='18.07.2026'!D19 -> 0 | V17: ='20.07.2026'!D19 -> 0 | W17: ='21.07.2026'!D19 -> 0 | X17: ='22.07.2026'!D19 -> 1 | Y17: ='23.07.2026'!D19 -> 0 | Z17: ='24.07.2026'!D19 -> 0 | AA17: ='25.07.2026'!D19 -> 0 | AC17: ='27.07.2026'!D19 -> 0 | AD17: ='28.07.2026'!D19 -> 0 | AE17: ='29.07.2026'!D19 -> 0 | AF17: ='30.07.2026'!D19 -> 0 | AG17: ='31.07.2026'!D19 -> 0 | AI17: =SUM(C17:AF17) -> 7
A18: 5 | B18: Rregullimi i lidhjes | C18: ='01.07.2026'!D20 -> 0 | D18: ='02.07.2026'!D20 -> 0 | E18: ='03.07.2026'!D20 -> 0 | F18: ='04.07.2026'!D20 -> 0 | H18: ='06.07.2026'!D20 -> 0 | I18: ='07.07.2026'!D20 -> 0 | J18: ='08.07.2026'!D20 -> 0 | K18: ='09.07.2026'!D20 -> 0 | L18: ='10.07.2026'!D20 -> 0 | M18: ='11.07.2026'!D20 -> 0 | O18: ='13.07.2026'!D20 -> 1 | P18: ='14.07.2026'!D20 -> 0 | Q18: ='15.07.2026'!D20 -> 0 | R18: ='16.07.2026'!D20 -> 0 | S18: ='17.07.2026'!D20 -> 0 | T18: ='18.07.2026'!D20 -> 0 | V18: ='20.07.2026'!D20 -> 0 | W18: ='21.07.2026'!D20 -> 0 | X18: ='22.07.2026'!D20 -> 0 | Y18: ='23.07.2026'!D20 -> 0 | Z18: ='24.07.2026'!D20 -> 0 | AA18: ='25.07.2026'!D20 -> 0 | AC18: ='27.07.2026'!D20 -> 0 | AD18: ='28.07.2026'!D20 -> 0 | AE18: ='29.07.2026'!D20 -> 0 | AF18: ='30.07.2026'!D20 -> 0 | AG18: ='31.07.2026'!D20 -> 0 | AI18: =SUM(C18:AF18) -> 1
A19: 6 | B19: Rregullim i fazimit, antenës, etj | C19: ='01.07.2026'!D21 -> 0 | D19: ='02.07.2026'!D21 -> 0 | E19: ='03.07.2026'!D21 -> 0 | F19: ='04.07.2026'!D21 -> 0 | H19: ='06.07.2026'!D21 -> 0 | I19: ='07.07.2026'!D21 -> 0 | J19: ='08.07.2026'!D21 -> 0 | K19: ='09.07.2026'!D21 -> 0 | L19: ='10.07.2026'!D21 -> 0 | M19: ='11.07.2026'!D21 -> 0 | O19: ='13.07.2026'!D21 -> 0 | P19: ='14.07.2026'!D21 -> 0 | Q19: ='15.07.2026'!D21 -> 0 | R19: ='16.07.2026'!D21 -> 0 | S19: ='17.07.2026'!D21 -> 0 | T19: ='18.07.2026'!D21 -> 0 | V19: ='20.07.2026'!D21 -> 0 | W19: ='21.07.2026'!D21 -> 0 | X19: ='22.07.2026'!D21 -> 0 | Y19: ='23.07.2026'!D21 -> 0 | Z19: ='24.07.2026'!D21 -> 0 | AA19: ='25.07.2026'!D21 -> 0 | AC19: ='27.07.2026'!D21 -> 0 | AD19: ='28.07.2026'!D21 -> 0 | AE19: ='29.07.2026'!D21 -> 4 | AF19: ='30.07.2026'!D21 -> 0 | AG19: ='31.07.2026'!D21 -> 0 | AI19: =SUM(C19:AF19) -> 4
A20: 7 | B20: Mbesin njehsorë të dëmtuar | C20: ='01.07.2026'!D22 -> 0 | D20: ='02.07.2026'!D22 -> 0 | E20: ='03.07.2026'!D22 -> 0 | F20: ='04.07.2026'!D22 -> 0 | H20: ='06.07.2026'!D22 -> 0 | I20: ='07.07.2026'!D22 -> 0 | J20: ='08.07.2026'!D22 -> 0 | K20: ='09.07.2026'!D22 -> 0 | L20: ='10.07.2026'!D22 -> 0 | M20: ='11.07.2026'!D22 -> 0 | O20: ='13.07.2026'!D22 -> 0 | P20: ='14.07.2026'!D22 -> 0 | Q20: ='15.07.2026'!D22 -> 0 | R20: ='16.07.2026'!D22 -> 0 | S20: ='17.07.2026'!D22 -> 0 | T20: ='18.07.2026'!D22 -> 0 | V20: ='20.07.2026'!D22 -> 0 | W20: ='21.07.2026'!D22 -> 0 | X20: ='22.07.2026'!D22 -> 0 | Y20: ='23.07.2026'!D22 -> 0 | Z20: ='24.07.2026'!D22 -> 0 | AA20: ='25.07.2026'!D22 -> 0 | AC20: ='27.07.2026'!D22 -> 0 | AD20: ='28.07.2026'!D22 -> 0 | AE20: ='29.07.2026'!D22 -> 2 | AF20: ='30.07.2026'!D22 -> 0 | AG20: ='31.07.2026'!D22 -> 0 | AI20: =SUM(C20:AF20) -> 2
A21: 8 | B21: Kontrollim sipas humbjeve | C21: ='01.07.2026'!D23 -> 0 | D21: ='02.07.2026'!D23 -> 0 | E21: ='03.07.2026'!D23 -> 0 | F21: ='04.07.2026'!D23 -> 0 | H21: ='06.07.2026'!D23 -> 0 | I21: ='07.07.2026'!D23 -> 0 | J21: ='08.07.2026'!D23 -> 0 | K21: ='09.07.2026'!D23 -> 0 | L21: ='10.07.2026'!D23 -> 0 | M21: ='11.07.2026'!D23 -> 0 | O21: ='13.07.2026'!D23 -> 0 | P21: ='14.07.2026'!D23 -> 0 | Q21: ='15.07.2026'!D23 -> 0 | R21: ='16.07.2026'!D23 -> 0 | S21: ='17.07.2026'!D23 -> 0 | T21: ='18.07.2026'!D23 -> 0 | V21: ='20.07.2026'!D23 -> 0 | W21: ='21.07.2026'!D23 -> 0 | X21: ='22.07.2026'!D23 -> 0 | Y21: ='23.07.2026'!D23 -> 0 | Z21: ='24.07.2026'!D23 -> 0 | AA21: ='25.07.2026'!D23 -> 0 | AC21: ='27.07.2026'!D23 -> 0 | AD21: ='28.07.2026'!D23 -> 0 | AE21: ='29.07.2026'!D23 -> 0 | AF21: ='30.07.2026'!D23 -> 0 | AG21: ='31.07.2026'!D23 -> 0 | AI21: =SUM(C21:AF21) -> 0
A22: 9 | B22: Rregullim pas vendosjes së ormanit të ri | C22: ='01.07.2026'!D24 -> 0 | D22: ='02.07.2026'!D24 -> 0 | E22: ='03.07.2026'!D24 -> 0 | F22: ='04.07.2026'!D24 -> 0 | H22: ='06.07.2026'!D24 -> 0 | I22: ='07.07.2026'!D24 -> 0 | J22: ='08.07.2026'!D24 -> 0 | K22: ='09.07.2026'!D24 -> 0 | L22: ='10.07.2026'!D24 -> 0 | M22: ='11.07.2026'!D24 -> 0 | O22: ='13.07.2026'!D24 -> 0 | P22: ='14.07.2026'!D24 -> 0 | Q22: ='15.07.2026'!D24 -> 0 | R22: ='16.07.2026'!D24 -> 0 | S22: ='17.07.2026'!D24 -> 0 | T22: ='18.07.2026'!D24 -> 0 | V22: ='20.07.2026'!D24 -> 0 | W22: ='21.07.2026'!D24 -> 0 | X22: ='22.07.2026'!D24 -> 0 | Y22: ='23.07.2026'!D24 -> 0 | Z22: ='24.07.2026'!D24 -> 0 | AA22: ='25.07.2026'!D24 -> 0 | AC22: ='27.07.2026'!D24 -> 0 | AD22: ='28.07.2026'!D24 -> 0 | AE22: ='29.07.2026'!D24 -> 0 | AF22: ='30.07.2026'!D24 -> 0 | AG22: ='31.07.2026'!D24 -> 0 | AI22: =SUM(C22:AF22) -> 0
A23: 10 | B23: Ndërrimet e TMRR pas ndërrimit të TR | C23: ='01.07.2026'!D25 -> 0 | D23: ='02.07.2026'!D25 -> 0 | E23: ='03.07.2026'!D25 -> 0 | F23: ='04.07.2026'!D25 -> 0 | H23: ='06.07.2026'!D25 -> 0 | I23: ='07.07.2026'!D25 -> 0 | J23: ='08.07.2026'!D25 -> 0 | K23: ='09.07.2026'!D25 -> 0 | L23: ='10.07.2026'!D25 -> 0 | M23: ='11.07.2026'!D25 -> 0 | O23: ='13.07.2026'!D25 -> 0 | P23: ='14.07.2026'!D25 -> 0 | Q23: ='15.07.2026'!D25 -> 0 | R23: ='16.07.2026'!D25 -> 0 | S23: ='17.07.2026'!D25 -> 0 | T23: ='18.07.2026'!D25 -> 0 | V23: ='20.07.2026'!D25 -> 0 | W23: ='21.07.2026'!D25 -> 0 | X23: ='22.07.2026'!D25 -> 0 | Y23: ='23.07.2026'!D25 -> 0 | Z23: ='24.07.2026'!D25 -> 0 | AA23: ='25.07.2026'!D25 -> 0 | AC23: ='27.07.2026'!D25 -> 0 | AD23: ='28.07.2026'!D25 -> 0 | AE23: ='29.07.2026'!D25 -> 0 | AF23: ='30.07.2026'!D25 -> 0 | AG23: ='31.07.2026'!D25 -> 0 | AI23: =SUM(C23:AF23) -> 0
A24: 11 | B24: Koncentrator | C24: ='01.07.2026'!D26 -> 0 | D24: ='02.07.2026'!D26 -> 0 | E24: ='03.07.2026'!D26 -> 0 | F24: ='04.07.2026'!D26 -> 0 | H24: ='06.07.2026'!D26 -> 1 | I24: ='07.07.2026'!D26 -> 0 | J24: ='08.07.2026'!D26 -> 0 | K24: ='09.07.2026'!D26 -> 0 | L24: ='10.07.2026'!D26 -> 0 | M24: ='11.07.2026'!D26 -> 0 | O24: ='13.07.2026'!D26 -> 1 | P24: ='14.07.2026'!D26 -> 0 | Q24: ='15.07.2026'!D26 -> 0 | R24: ='16.07.2026'!D26 -> 0 | S24: ='17.07.2026'!D26 -> 0 | T24: ='18.07.2026'!D26 -> 0 | V24: ='20.07.2026'!D26 -> 0 | W24: ='21.07.2026'!D26 -> 0 | X24: ='22.07.2026'!D26 -> 0 | Y24: ='23.07.2026'!D26 -> 0 | Z24: ='24.07.2026'!D26 -> 0 | AA24: ='25.07.2026'!D26 -> 0 | AC24: ='27.07.2026'!D26 -> 0 | AD24: ='28.07.2026'!D26 -> 0 | AE24: ='29.07.2026'!D26 -> 1 | AF24: ='30.07.2026'!D26 -> 0 | AG24: ='31.07.2026'!D26 -> 0 | AI24: =SUM(C24:AF24) -> 3
B26: DIREKT
A27: 1 | B27: Lidhje të reja | C27: ='01.07.2026'!D29 -> 0 | D27: ='02.07.2026'!D29 -> 0 | E27: ='03.07.2026'!D29 -> 0 | F27: ='04.07.2026'!D29 -> 0 | H27: ='06.07.2026'!D29 -> 0 | I27: ='07.07.2026'!D29 -> 0 | J27: ='08.07.2026'!D29 -> 0 | K27: ='09.07.2026'!D29 -> 0 | L27: ='10.07.2026'!D29 -> 0 | M27: ='11.07.2026'!D29 -> 0 | O27: ='13.07.2026'!D29 -> 0 | P27: ='14.07.2026'!D29 -> 0 | Q27: ='15.07.2026'!D29 -> 0 | R27: ='16.07.2026'!D29 -> 0 | S27: ='17.07.2026'!D29 -> 0 | T27: ='18.07.2026'!D29 -> 0 | V27: ='20.07.2026'!D29 -> 0 | W27: ='21.07.2026'!D29 -> 0 | X27: ='22.07.2026'!D29 -> 0 | Y27: ='23.07.2026'!D29 -> 0 | Z27: ='24.07.2026'!D29 -> 0 | AA27: ='25.07.2026'!D29 -> 0 | AC27: ='27.07.2026'!D29 -> 0 | AD27: ='28.07.2026'!D29 -> 0 | AE27: ='29.07.2026'!D29 -> 0 | AF27: ='30.07.2026'!D29 -> 0 | AG27: ='31.07.2026'!D29 -> 0 | AI27: =SUM(C27:AF27) -> 0
A28: 2 | B28: Ndërrime | C28: ='01.07.2026'!D30 -> 0 | D28: ='02.07.2026'!D30 -> 1 | E28: ='03.07.2026'!D30 -> 1 | F28: ='04.07.2026'!D30 -> 0 | H28: ='06.07.2026'!D30 -> 0 | I28: ='07.07.2026'!D30 -> 0 | J28: ='08.07.2026'!D30 -> 0 | K28: ='09.07.2026'!D30 -> 0 | L28: ='10.07.2026'!D30 -> 0 | M28: ='11.07.2026'!D30 -> 0 | O28: ='13.07.2026'!D30 -> 0 | P28: ='14.07.2026'!D30 -> 0 | Q28: ='15.07.2026'!D30 -> 0 | R28: ='16.07.2026'!D30 -> 0 | S28: ='17.07.2026'!D30 -> 0 | T28: ='18.07.2026'!D30 -> 0 | V28: ='20.07.2026'!D30 -> 0 | W28: ='21.07.2026'!D30 -> 0 | X28: ='22.07.2026'!D30 -> 0 | Y28: ='23.07.2026'!D30 -> 0 | Z28: ='24.07.2026'!D30 -> 0 | AA28: ='25.07.2026'!D30 -> 0 | AC28: ='27.07.2026'!D30 -> 0 | AD28: ='28.07.2026'!D30 -> 0 | AE28: ='29.07.2026'!D30 -> 0 | AF28: ='30.07.2026'!D30 -> 0 | AG28: ='31.07.2026'!D30 -> 0 | AI28: =SUM(C28:AF28) -> 2
A29: 3 | B29: PLC | C29: ='01.07.2026'!D31 -> 0 | D29: ='02.07.2026'!D31 -> 0 | E29: ='03.07.2026'!D31 -> 0 | F29: ='04.07.2026'!D31 -> 0 | H29: ='06.07.2026'!D31 -> 0 | I29: ='07.07.2026'!D31 -> 0 | J29: ='08.07.2026'!D31 -> 0 | K29: ='09.07.2026'!D31 -> 0 | L29: ='10.07.2026'!D31 -> 0 | M29: ='11.07.2026'!D31 -> 0 | O29: ='13.07.2026'!D31 -> 0 | P29: ='14.07.2026'!D31 -> 0 | Q29: ='15.07.2026'!D31 -> 0 | R29: ='16.07.2026'!D31 -> 0 | S29: ='17.07.2026'!D31 -> 0 | T29: ='18.07.2026'!D31 -> 0 | V29: ='20.07.2026'!D31 -> 0 | W29: ='21.07.2026'!D31 -> 0 | X29: ='22.07.2026'!D31 -> 0 | Y29: ='23.07.2026'!D31 -> 0 | Z29: ='24.07.2026'!D31 -> 0 | AA29: ='25.07.2026'!D31 -> 0 | AC29: ='27.07.2026'!D31 -> 0 | AD29: ='28.07.2026'!D31 -> 0 | AE29: ='29.07.2026'!D31 -> 0 | AF29: ='30.07.2026'!D31 -> 0 | AG29: ='31.07.2026'!D31 -> 0 | AI29: =SUM(C29:AF29) -> 0
A30: 4 | B30: Kontrollim me ZERA | C30: ='01.07.2026'!D32 -> 0 | D30: ='02.07.2026'!D32 -> 0 | E30: ='03.07.2026'!D32 -> 0 | F30: ='04.07.2026'!D32 -> 0 | H30: ='06.07.2026'!D32 -> 0 | I30: ='07.07.2026'!D32 -> 0 | J30: ='08.07.2026'!D32 -> 0 | K30: ='09.07.2026'!D32 -> 0 | L30: ='10.07.2026'!D32 -> 0 | M30: ='11.07.2026'!D32 -> 0 | O30: ='13.07.2026'!D32 -> 0 | P30: ='14.07.2026'!D32 -> 0 | Q30: ='15.07.2026'!D32 -> 0 | R30: ='16.07.2026'!D32 -> 0 | S30: ='17.07.2026'!D32 -> 0 | T30: ='18.07.2026'!D32 -> 0 | V30: ='20.07.2026'!D32 -> 0 | W30: ='21.07.2026'!D32 -> 0 | X30: ='22.07.2026'!D32 -> 0 | Y30: ='23.07.2026'!D32 -> 0 | Z30: ='24.07.2026'!D32 -> 0 | AA30: ='25.07.2026'!D32 -> 0 | AC30: ='27.07.2026'!D32 -> 0 | AD30: ='28.07.2026'!D32 -> 2 | AE30: ='29.07.2026'!D32 -> 0 | AF30: ='30.07.2026'!D32 -> 0 | AG30: ='31.07.2026'!D32 -> 0 | AI30: =SUM(C30:AF30) -> 2
A31: 5 | B31: Rregullim komunikimit dhe tjera | C31: ='01.07.2026'!D33 -> 15 | D31: ='02.07.2026'!D33 -> 0 | E31: ='03.07.2026'!D33 -> 0 | F31: ='04.07.2026'!D33 -> 0 | H31: ='06.07.2026'!D33 -> 0 | I31: ='07.07.2026'!D33 -> 0 | J31: ='08.07.2026'!D33 -> 0 | K31: ='09.07.2026'!D33 -> 0 | L31: ='10.07.2026'!D33 -> 0 | M31: ='11.07.2026'!D33 -> 0 | O31: ='13.07.2026'!D33 -> 0 | P31: ='14.07.2026'!D33 -> 0 | Q31: ='15.07.2026'!D33 -> 0 | R31: ='16.07.2026'!D33 -> 0 | S31: ='17.07.2026'!D33 -> 0 | T31: ='18.07.2026'!D33 -> 0 | V31: ='20.07.2026'!D33 -> 1 | W31: ='21.07.2026'!D33 -> 10 | X31: ='22.07.2026'!D33 -> 44 | Y31: ='23.07.2026'!D33 -> 8 | Z31: ='24.07.2026'!D33 -> 13 | AA31: ='25.07.2026'!D33 -> 0 | AC31: ='27.07.2026'!D33 -> 16 | AD31: ='28.07.2026'!D33 -> 8 | AE31: ='29.07.2026'!D33 -> 7 | AF31: ='30.07.2026'!D33 -> 19 | AG31: ='31.07.2026'!D33 -> 5 | AI31: =SUM(C31:AF31) -> 141

Sheet DPE
A1: DPE - RAPORT MUJOR - QERSHOR 2026
A2: NR | B2: KOMERCIAL | C2: 1 | D2: 2 | E2: 3 | F2: 4 | G2: 5 | H2: 6 | I2: 7 | J2: 8 | K2: 9 | L2: 10 | M2: 11 | N2: 12 | O2: 13 | P2: 14 | Q2: 15 | R2: 16 | S2: 17 | T2: 18 | U2: 19 | V2: 20 | W2: 21 | X2: 22 | Y2: 23 | Z2: 24 | AA2: 25 | AB2: 26 | AC2: 27 | AD2: 28 | AE2: 29 | AF2: 30 | AG2: 31 | AI2: Totali
A3: 1 | B3: Kontrollimi periodik i GM | C3: ='01.07.2026'!E5 -> 3 | D3: ='02.07.2026'!E5 -> 0 | E3: ='03.07.2026'!E5 -> 0 | F3: ='04.07.2026'!E5 -> 5 | H3: ='06.07.2026'!E5 -> 2 | I3: ='07.07.2026'!E5 -> 6 | J3: ='08.07.2026'!E5 -> 2 | K3: ='09.07.2026'!E5 -> 1 | L3: ='10.07.2026'!E5 -> 3 | M3: ='11.07.2026'!E5 -> 0 | O3: ='13.07.2026'!E5 -> 3 | P3: ='14.07.2026'!E5 -> 2 | Q3: ='15.07.2026'!E5 -> 3 | R3: ='16.07.2026'!E5 -> 2 | S3: ='17.07.2026'!E5 -> 6 | T3: ='18.07.2026'!E5 -> 0 | V3: ='20.07.2026'!E5 -> 0 | W3: ='21.07.2026'!E5 -> 0 | X3: ='22.07.2026'!E5 -> 3 | Y3: ='23.07.2026'!E5 -> 1 | Z3: ='24.07.2026'!E5 -> 0 | AA3: ='25.07.2026'!E5 -> 0 | AC3: ='27.07.2026'!E5 -> 0 | AD3: ='28.07.2026'!E5 -> 1 | AE3: ='29.07.2026'!E5 -> 0 | AF3: ='30.07.2026'!E5 -> 0 | AG3: ='31.07.2026'!E5 -> 0 | AI3: =SUM(C3:AF3) -> 43
A4: 2 | B4: Kontrollimi sipas DV i GM | C4: ='01.07.2026'!E6 -> 0 | D4: ='02.07.2026'!E6 -> 0 | E4: ='03.07.2026'!E6 -> 0 | F4: ='04.07.2026'!E6 -> 0 | H4: ='06.07.2026'!E6 -> 1 | I4: ='07.07.2026'!E6 -> 0 | J4: ='08.07.2026'!E6 -> 0 | K4: ='09.07.2026'!E6 -> 0 | L4: ='10.07.2026'!E6 -> 0 | M4: ='11.07.2026'!E6 -> 0 | O4: ='13.07.2026'!E6 -> 0 | P4: ='14.07.2026'!E6 -> 0 | Q4: ='15.07.2026'!E6 -> 0 | R4: ='16.07.2026'!E6 -> 0 | S4: ='17.07.2026'!E6 -> 0 | T4: ='18.07.2026'!E6 -> 0 | V4: ='20.07.2026'!E6 -> 0 | W4: ='21.07.2026'!E6 -> 0 | X4: ='22.07.2026'!E6 -> 0 | Y4: ='23.07.2026'!E6 -> 0 | Z4: ='24.07.2026'!E6 -> 0 | AA4: ='25.07.2026'!E6 -> 0 | AC4: ='27.07.2026'!E6 -> 0 | AD4: ='28.07.2026'!E6 -> 0 | AE4: ='29.07.2026'!E6 -> 0 | AF4: ='30.07.2026'!E6 -> 0 | AG4: ='31.07.2026'!E6 -> 0 | AI4: =SUM(C4:AF4) -> 1
A5: 3 | B5: Ndërrimi i TMRR-ve | C5: ='01.07.2026'!E7 -> 0 | D5: ='02.07.2026'!E7 -> 0 | E5: ='03.07.2026'!E7 -> 0 | F5: ='04.07.2026'!E7 -> 0 | H5: ='06.07.2026'!E7 -> 0 | I5: ='07.07.2026'!E7 -> 0 | J5: ='08.07.2026'!E7 -> 0 | K5: ='09.07.2026'!E7 -> 0 | L5: ='10.07.2026'!E7 -> 0 | M5: ='11.07.2026'!E7 -> 0 | O5: ='13.07.2026'!E7 -> 0 | P5: ='14.07.2026'!E7 -> 0 | Q5: ='15.07.2026'!E7 -> 0 | R5: ='16.07.2026'!E7 -> 0 | S5: ='17.07.2026'!E7 -> 0 | T5: ='18.07.2026'!E7 -> 0 | V5: ='20.07.2026'!E7 -> 0 | W5: ='21.07.2026'!E7 -> 0 | X5: ='22.07.2026'!E7 -> 0 | Y5: ='23.07.2026'!E7 -> 0 | Z5: ='24.07.2026'!E7 -> 0 | AA5: ='25.07.2026'!E7 -> 0 | AC5: ='27.07.2026'!E7 -> 0 | AD5: ='28.07.2026'!E7 -> 0 | AE5: ='29.07.2026'!E7 -> 0 | AF5: ='30.07.2026'!E7 -> 1 | AG5: ='31.07.2026'!E7 -> 0 | AI5: =SUM(C5:AF5) -> 1
A6: 4 | B6: Ndërrimi i njehsorit | C6: ='01.07.2026'!E8 -> 0 | D6: ='02.07.2026'!E8 -> 1 | E6: ='03.07.2026'!E8 -> 4 | F6: ='04.07.2026'!E8 -> 0 | H6: ='06.07.2026'!E8 -> 0 | I6: ='07.07.2026'!E8 -> 0 | J6: ='08.07.2026'!E8 -> 0 | K6: ='09.07.2026'!E8 -> 0 | L6: ='10.07.2026'!E8 -> 0 | M6: ='11.07.2026'!E8 -> 0 | O6: ='13.07.2026'!E8 -> 0 | P6: ='14.07.2026'!E8 -> 0 | Q6: ='15.07.2026'!E8 -> 0 | R6: ='16.07.2026'!E8 -> 0 | S6: ='17.07.2026'!E8 -> 0 | T6: ='18.07.2026'!E8 -> 0 | V6: ='20.07.2026'!E8 -> 0 | W6: ='21.07.2026'!E8 -> 0 | X6: ='22.07.2026'!E8 -> 0 | Y6: ='23.07.2026'!E8 -> 0 | Z6: ='24.07.2026'!E8 -> 1 | AA6: ='25.07.2026'!E8 -> 0 | AC6: ='27.07.2026'!E8 -> 0 | AD6: ='28.07.2026'!E8 -> 0 | AE6: ='29.07.2026'!E8 -> 0 | AF6: ='30.07.2026'!E8 -> 1 | AG6: ='31.07.2026'!E8 -> 0 | AI6: =SUM(C6:AF6) -> 7
A7: 5 | B7: Montimet e GM me PEE | C7: ='01.07.2026'!E9 -> 0 | D7: ='02.07.2026'!E9 -> 0 | E7: ='03.07.2026'!E9 -> 0 | F7: ='04.07.2026'!E9 -> 1 | H7: ='06.07.2026'!E9 -> 0 | I7: ='07.07.2026'!E9 -> 0 | J7: ='08.07.2026'!E9 -> 0 | K7: ='09.07.2026'!E9 -> 0 | L7: ='10.07.2026'!E9 -> 0 | M7: ='11.07.2026'!E9 -> 0 | O7: ='13.07.2026'!E9 -> 0 | P7: ='14.07.2026'!E9 -> 0 | Q7: ='15.07.2026'!E9 -> 0 | R7: ='16.07.2026'!E9 -> 0 | S7: ='17.07.2026'!E9 -> 0 | T7: ='18.07.2026'!E9 -> 0 | V7: ='20.07.2026'!E9 -> 0 | W7: ='21.07.2026'!E9 -> 0 | X7: ='22.07.2026'!E9 -> 0 | Y7: ='23.07.2026'!E9 -> 0 | Z7: ='24.07.2026'!E9 -> 0 | AA7: ='25.07.2026'!E9 -> 0 | AC7: ='27.07.2026'!E9 -> 0 | AD7: ='28.07.2026'!E9 -> 0 | AE7: ='29.07.2026'!E9 -> 0 | AF7: ='30.07.2026'!E9 -> 0 | AG7: ='31.07.2026'!E9 -> 0 | AI7: =SUM(C7:AF7) -> 1
A8: 6 | B8: Kontrollime me kërkesë të konsumatorit | C8: ='01.07.2026'!E10 -> 0 | D8: ='02.07.2026'!E10 -> 0 | E8: ='03.07.2026'!E10 -> 0 | F8: ='04.07.2026'!E10 -> 0 | H8: ='06.07.2026'!E10 -> 0 | I8: ='07.07.2026'!E10 -> 0 | J8: ='08.07.2026'!E10 -> 0 | K8: ='09.07.2026'!E10 -> 0 | L8: ='10.07.2026'!E10 -> 0 | M8: ='11.07.2026'!E10 -> 0 | O8: ='13.07.2026'!E10 -> 0 | P8: ='14.07.2026'!E10 -> 0 | Q8: ='15.07.2026'!E10 -> 0 | R8: ='16.07.2026'!E10 -> 0 | S8: ='17.07.2026'!E10 -> 0 | T8: ='18.07.2026'!E10 -> 0 | V8: ='20.07.2026'!E10 -> 0 | W8: ='21.07.2026'!E10 -> 0 | X8: ='22.07.2026'!E10 -> 0 | Y8: ='23.07.2026'!E10 -> 0 | Z8: ='24.07.2026'!E10 -> 0 | AA8: ='25.07.2026'!E10 -> 0 | AC8: ='27.07.2026'!E10 -> 0 | AD8: ='28.07.2026'!E10 -> 0 | AE8: ='29.07.2026'!E10 -> 0 | AF8: ='30.07.2026'!E10 -> 0 | AG8: ='31.07.2026'!E10 -> 0 | AI8: =SUM(C8:AF8) -> 0
A9: 7 | B9: Rregullimi i lidhjes | C9: ='01.07.2026'!E11 -> 0 | D9: ='02.07.2026'!E11 -> 0 | E9: ='03.07.2026'!E11 -> 0 | F9: ='04.07.2026'!E11 -> 0 | H9: ='06.07.2026'!E11 -> 1 | I9: ='07.07.2026'!E11 -> 0 | J9: ='08.07.2026'!E11 -> 0 | K9: ='09.07.2026'!E11 -> 0 | L9: ='10.07.2026'!E11 -> 0 | M9: ='11.07.2026'!E11 -> 0 | O9: ='13.07.2026'!E11 -> 0 | P9: ='14.07.2026'!E11 -> 0 | Q9: ='15.07.2026'!E11 -> 0 | R9: ='16.07.2026'!E11 -> 0 | S9: ='17.07.2026'!E11 -> 0 | T9: ='18.07.2026'!E11 -> 0 | V9: ='20.07.2026'!E11 -> 0 | W9: ='21.07.2026'!E11 -> 0 | X9: ='22.07.2026'!E11 -> 0 | Y9: ='23.07.2026'!E11 -> 0 | Z9: ='24.07.2026'!E11 -> 0 | AA9: ='25.07.2026'!E11 -> 0 | AC9: ='27.07.2026'!E11 -> 0 | AD9: ='28.07.2026'!E11 -> 0 | AE9: ='29.07.2026'!E11 -> 0 | AF9: ='30.07.2026'!E11 -> 0 | AG9: ='31.07.2026'!E11 -> 0 | AI9: =SUM(C9:AF9) -> 1
A10: 8 | B10: Rregullim i komunikimit | C10: ='01.07.2026'!E12 -> 0 | D10: ='02.07.2026'!E12 -> 0 | E10: ='03.07.2026'!E12 -> 0 | F10: ='04.07.2026'!E12 -> 0 | H10: ='06.07.2026'!E12 -> 3 | I10: ='07.07.2026'!E12 -> 0 | J10: ='08.07.2026'!E12 -> 0 | K10: ='09.07.2026'!E12 -> 0 | L10: ='10.07.2026'!E12 -> 0 | M10: ='11.07.2026'!E12 -> 0 | O10: ='13.07.2026'!E12 -> 0 | P10: ='14.07.2026'!E12 -> 0 | Q10: ='15.07.2026'!E12 -> 0 | R10: ='16.07.2026'!E12 -> 0 | S10: ='17.07.2026'!E12 -> 0 | T10: ='18.07.2026'!E12 -> 0 | V10: ='20.07.2026'!E12 -> 0 | W10: ='21.07.2026'!E12 -> 0 | X10: ='22.07.2026'!E12 -> 0 | Y10: ='23.07.2026'!E12 -> 0 | Z10: ='24.07.2026'!E12 -> 0 | AA10: ='25.07.2026'!E12 -> 0 | AC10: ='27.07.2026'!E12 -> 0 | AD10: ='28.07.2026'!E12 -> 0 | AE10: ='29.07.2026'!E12 -> 0 | AF10: ='30.07.2026'!E12 -> 0 | AG10: ='31.07.2026'!E12 -> 0 | AI10: =SUM(C10:AF10) -> 3
A11: 9 | B11: Lexim | C11: ='01.07.2026'!E13 -> 25 | D11: ='02.07.2026'!E13 -> 9 | E11: ='03.07.2026'!E13 -> 0 | F11: ='04.07.2026'!E13 -> 0 | H11: ='06.07.2026'!E13 -> 0 | I11: ='07.07.2026'!E13 -> 0 | J11: ='08.07.2026'!E13 -> 0 | K11: ='09.07.2026'!E13 -> 0 | L11: ='10.07.2026'!E13 -> 0 | M11: ='11.07.2026'!E13 -> 0 | O11: ='13.07.2026'!E13 -> 0 | P11: ='14.07.2026'!E13 -> 0 | Q11: ='15.07.2026'!E13 -> 0 | R11: ='16.07.2026'!E13 -> 0 | S11: ='17.07.2026'!E13 -> 0 | T11: ='18.07.2026'!E13 -> 0 | V11: ='20.07.2026'!E13 -> 0 | W11: ='21.07.2026'!E13 -> 36 | X11: ='22.07.2026'!E13 -> 30 | Y11: ='23.07.2026'!E13 -> 22 | Z11: ='24.07.2026'!E13 -> 28 | AA11: ='25.07.2026'!E13 -> 0 | AC11: ='27.07.2026'!E13 -> 30 | AD11: ='28.07.2026'!E13 -> 20 | AE11: ='29.07.2026'!E13 -> 40 | AF11: ='30.07.2026'!E13 -> 20 | AG11: ='31.07.2026'!E13 -> 30 | AI11: =SUM(C11:AF11) -> 260
B13: TRAFOREGJIONE
A14: 1 | B14: Kontrollimi i GM | C14: ='01.07.2026'!E16 -> 0 | D14: ='02.07.2026'!E16 -> 3 | E14: ='03.07.2026'!E16 -> 0 | F14: ='04.07.2026'!E16 -> 2 | H14: ='06.07.2026'!E16 -> 5 | I14: ='07.07.2026'!E16 -> 3 | J14: ='08.07.2026'!E16 -> 14 | K14: ='09.07.2026'!E16 -> 8 | L14: ='10.07.2026'!E16 -> 12 | M14: ='11.07.2026'!E16 -> 0 | O14: ='13.07.2026'!E16 -> 12 | P14: ='14.07.2026'!E16 -> 11 | Q14: ='15.07.2026'!E16 -> 10 | R14: ='16.07.2026'!E16 -> 21 | S14: ='17.07.2026'!E16 -> 10 | T14: ='18.07.2026'!E16 -> 0 | V14: ='20.07.2026'!E16 -> 10 | W14: ='21.07.2026'!E16 -> 0 | X14: ='22.07.2026'!E16 -> 4 | Y14: ='23.07.2026'!E16 -> 1 | Z14: ='24.07.2026'!E16 -> 0 | AA14: ='25.07.2026'!E16 -> 0 | AC14: ='27.07.2026'!E16 -> 0 | AD14: ='28.07.2026'!E16 -> 1 | AE14: ='29.07.2026'!E16 -> 0 | AF14: ='30.07.2026'!E16 -> 0 | AG14: ='31.07.2026'!E16 -> 0 | AI14: =SUM(C14:AF14) -> 127
A15: 2 | B15: Nderrimi i TMRR-ve | C15: ='01.07.2026'!E17 -> 0 | D15: ='02.07.2026'!E17 -> 0 | E15: ='03.07.2026'!E17 -> 0 | F15: ='04.07.2026'!E17 -> 0 | H15: ='06.07.2026'!E17 -> 0 | I15: ='07.07.2026'!E17 -> 1 | J15: ='08.07.2026'!E17 -> 1 | K15: ='09.07.2026'!E17 -> 0 | L15: ='10.07.2026'!E17 -> 0 | M15: ='11.07.2026'!E17 -> 0 | O15: ='13.07.2026'!E17 -> 0 | P15: ='14.07.2026'!E17 -> 0 | Q15: ='15.07.2026'!E17 -> 0 | R15: ='16.07.2026'!E17 -> 0 | S15: ='17.07.2026'!E17 -> 0 | T15: ='18.07.2026'!E17 -> 0 | V15: ='20.07.2026'!E17 -> 0 | W15: ='21.07.2026'!E17 -> 1 | X15: ='22.07.2026'!E17 -> 0 | Y15: ='23.07.2026'!E17 -> 0 | Z15: ='24.07.2026'!E17 -> 0 | AA15: ='25.07.2026'!E17 -> 0 | AC15: ='27.07.2026'!E17 -> 1 | AD15: ='28.07.2026'!E17 -> 0 | AE15: ='29.07.2026'!E17 -> 0 | AF15: ='30.07.2026'!E17 -> 0 | AG15: ='31.07.2026'!E17 -> 1 | AI15: =SUM(C15:AF15) -> 4
A16: 3 | B16: Ndrrimet i njehsorit | C16: ='01.07.2026'!E18 -> 0 | D16: ='02.07.2026'!E18 -> 3 | E16: ='03.07.2026'!E18 -> 0 | F16: ='04.07.2026'!E18 -> 0 | H16: ='06.07.2026'!E18 -> 0 | I16: ='07.07.2026'!E18 -> 0 | J16: ='08.07.2026'!E18 -> 0 | K16: ='09.07.2026'!E18 -> 0 | L16: ='10.07.2026'!E18 -> 0 | M16: ='11.07.2026'!E18 -> 0 | O16: ='13.07.2026'!E18 -> 0 | P16: ='14.07.2026'!E18 -> 0 | Q16: ='15.07.2026'!E18 -> 1 | R16: ='16.07.2026'!E18 -> 0 | S16: ='17.07.2026'!E18 -> 0 | T16: ='18.07.2026'!E18 -> 0 | V16: ='20.07.2026'!E18 -> 0 | W16: ='21.07.2026'!E18 -> 0 | X16: ='22.07.2026'!E18 -> 0 | Y16: ='23.07.2026'!E18 -> 0 | Z16: ='24.07.2026'!E18 -> 0 | AA16: ='25.07.2026'!E18 -> 0 | AC16: ='27.07.2026'!E18 -> 0 | AD16: ='28.07.2026'!E18 -> 0 | AE16: ='29.07.2026'!E18 -> 0 | AF16: ='30.07.2026'!E18 -> 0 | AG16: ='31.07.2026'!E18 -> 0 | AI16: =SUM(C16:AF16) -> 4
A17: 4 | B17: Montimet e GM | C17: ='01.07.2026'!E19 -> 0 | D17: ='02.07.2026'!E19 -> 0 | E17: ='03.07.2026'!E19 -> 0 | F17: ='04.07.2026'!E19 -> 0 | H17: ='06.07.2026'!E19 -> 0 | I17: ='07.07.2026'!E19 -> 0 | J17: ='08.07.2026'!E19 -> 0 | K17: ='09.07.2026'!E19 -> 0 | L17: ='10.07.2026'!E19 -> 1 | M17: ='11.07.2026'!E19 -> 0 | O17: ='13.07.2026'!E19 -> 0 | P17: ='14.07.2026'!E19 -> 0 | Q17: ='15.07.2026'!E19 -> 0 | R17: ='16.07.2026'!E19 -> 0 | S17: ='17.07.2026'!E19 -> 0 | T17: ='18.07.2026'!E19 -> 0 | V17: ='20.07.2026'!E19 -> 1 | W17: ='21.07.2026'!E19 -> 0 | X17: ='22.07.2026'!E19 -> 1 | Y17: ='23.07.2026'!E19 -> 1 | Z17: ='24.07.2026'!E19 -> 1 | AA17: ='25.07.2026'!E19 -> 0 | AC17: ='27.07.2026'!E19 -> 0 | AD17: ='28.07.2026'!E19 -> 0 | AE17: ='29.07.2026'!E19 -> 0 | AF17: ='30.07.2026'!E19 -> 0 | AG17: ='31.07.2026'!E19 -> 0 | AI17: =SUM(C17:AF17) -> 5
A18: 5 | B18: Rregullimi i lidhjes | C18: ='01.07.2026'!E20 -> 0 | D18: ='02.07.2026'!E20 -> 0 | E18: ='03.07.2026'!E20 -> 0 | F18: ='04.07.2026'!E20 -> 0 | H18: ='06.07.2026'!E20 -> 2 | I18: ='07.07.2026'!E20 -> 0 | J18: ='08.07.2026'!E20 -> 0 | K18: ='09.07.2026'!E20 -> 0 | L18: ='10.07.2026'!E20 -> 0 | M18: ='11.07.2026'!E20 -> 0 | O18: ='13.07.2026'!E20 -> 0 | P18: ='14.07.2026'!E20 -> 0 | Q18: ='15.07.2026'!E20 -> 0 | R18: ='16.07.2026'!E20 -> 0 | S18: ='17.07.2026'!E20 -> 0 | T18: ='18.07.2026'!E20 -> 0 | V18: ='20.07.2026'!E20 -> 0 | W18: ='21.07.2026'!E20 -> 0 | X18: ='22.07.2026'!E20 -> 0 | Y18: ='23.07.2026'!E20 -> 0 | Z18: ='24.07.2026'!E20 -> 0 | AA18: ='25.07.2026'!E20 -> 0 | AC18: ='27.07.2026'!E20 -> 0 | AD18: ='28.07.2026'!E20 -> 0 | AE18: ='29.07.2026'!E20 -> 0 | AF18: ='30.07.2026'!E20 -> 0 | AG18: ='31.07.2026'!E20 -> 0 | AI18: =SUM(C18:AF18) -> 2
A19: 6 | B19: Rregullim i fazimit, antenës, etj | C19: ='01.07.2026'!E21 -> 0 | D19: ='02.07.2026'!E21 -> 0 | E19: ='03.07.2026'!E21 -> 0 | F19: ='04.07.2026'!E21 -> 0 | H19: ='06.07.2026'!E21 -> 0 | I19: ='07.07.2026'!E21 -> 0 | J19: ='08.07.2026'!E21 -> 0 | K19: ='09.07.2026'!E21 -> 0 | L19: ='10.07.2026'!E21 -> 0 | M19: ='11.07.2026'!E21 -> 0 | O19: ='13.07.2026'!E21 -> 0 | P19: ='14.07.2026'!E21 -> 1 | Q19: ='15.07.2026'!E21 -> 0 | R19: ='16.07.2026'!E21 -> 0 | S19: ='17.07.2026'!E21 -> 0 | T19: ='18.07.2026'!E21 -> 0 | V19: ='20.07.2026'!E21 -> 0 | W19: ='21.07.2026'!E21 -> 0 | X19: ='22.07.2026'!E21 -> 0 | Y19: ='23.07.2026'!E21 -> 0 | Z19: ='24.07.2026'!E21 -> 0 | AA19: ='25.07.2026'!E21 -> 0 | AC19: ='27.07.2026'!E21 -> 0 | AD19: ='28.07.2026'!E21 -> 0 | AE19: ='29.07.2026'!E21 -> 0 | AF19: ='30.07.2026'!E21 -> 0 | AG19: ='31.07.2026'!E21 -> 0 | AI19: =SUM(C19:AF19) -> 1
A20: 7 | B20: Mbesin njehsorë të dëmtuar | C20: ='01.07.2026'!E22 -> 0 | D20: ='02.07.2026'!E22 -> 0 | E20: ='03.07.2026'!E22 -> 0 | F20: ='04.07.2026'!E22 -> 0 | H20: ='06.07.2026'!E22 -> 0 | I20: ='07.07.2026'!E22 -> 0 | J20: ='08.07.2026'!E22 -> 0 | K20: ='09.07.2026'!E22 -> 0 | L20: ='10.07.2026'!E22 -> 0 | M20: ='11.07.2026'!E22 -> 0 | O20: ='13.07.2026'!E22 -> 0 | P20: ='14.07.2026'!E22 -> 0 | Q20: ='15.07.2026'!E22 -> 0 | R20: ='16.07.2026'!E22 -> 0 | S20: ='17.07.2026'!E22 -> 0 | T20: ='18.07.2026'!E22 -> 0 | V20: ='20.07.2026'!E22 -> 0 | W20: ='21.07.2026'!E22 -> 0 | X20: ='22.07.2026'!E22 -> 0 | Y20: ='23.07.2026'!E22 -> 0 | Z20: ='24.07.2026'!E22 -> 0 | AA20: ='25.07.2026'!E22 -> 0 | AC20: ='27.07.2026'!E22 -> 0 | AD20: ='28.07.2026'!E22 -> 0 | AE20: ='29.07.2026'!E22 -> 0 | AF20: ='30.07.2026'!E22 -> 0 | AG20: ='31.07.2026'!E22 -> 0 | AI20: =SUM(C20:AF20) -> 0
A21: 8 | B21: Kontrollim sipas humbjeve | C21: ='01.07.2026'!E23 -> 0 | D21: ='02.07.2026'!E23 -> 0 | E21: ='03.07.2026'!E23 -> 0 | F21: ='04.07.2026'!E23 -> 0 | H21: ='06.07.2026'!E23 -> 0 | I21: ='07.07.2026'!E23 -> 0 | J21: ='08.07.2026'!E23 -> 0 | K21: ='09.07.2026'!E23 -> 0 | L21: ='10.07.2026'!E23 -> 0 | M21: ='11.07.2026'!E23 -> 0 | O21: ='13.07.2026'!E23 -> 0 | P21: ='14.07.2026'!E23 -> 0 | Q21: ='15.07.2026'!E23 -> 0 | R21: ='16.07.2026'!E23 -> 0 | S21: ='17.07.2026'!E23 -> 0 | T21: ='18.07.2026'!E23 -> 0 | V21: ='20.07.2026'!E23 -> 0 | W21: ='21.07.2026'!E23 -> 0 | X21: ='22.07.2026'!E23 -> 0 | Y21: ='23.07.2026'!E23 -> 0 | Z21: ='24.07.2026'!E23 -> 0 | AA21: ='25.07.2026'!E23 -> 0 | AC21: ='27.07.2026'!E23 -> 0 | AD21: ='28.07.2026'!E23 -> 0 | AE21: ='29.07.2026'!E23 -> 0 | AF21: ='30.07.2026'!E23 -> 0 | AG21: ='31.07.2026'!E23 -> 0 | AI21: =SUM(C21:AF21) -> 0
